<?xml version="1.0" encoding="utf-8"?>
<!-- This URDF was automatically created by SolidWorks to URDF Exporter! Originally created by Stephen Brawner (brawner@gmail.com) 
     Commit Version: 1.6.0-4-g7f85cfe  Build Version: 1.6.7995.38578
     For more information, please see http://wiki.ros.org/sw_urdf_exporter -->
<robot
  name="car_assem3">
  <link
    name="base_link">
    <inertial>
      <origin
        xyz="-3.71298564605664E-18 0.0321638063426192 0.00145191927012034"
        rpy="0 0 0" />
      <mass
        value="12.8455748904513" />
      <inertia
        ixx="0.625049233645234"
        ixy="1.92804480905926E-18"
        ixz="-2.9337095024267E-17"
        iyy="0.798889835201529"
        iyz="0.000413371338955771"
        izz="0.213323829100684" />
    </inertial>
    <visual>
      <origin
        xyz="0 0 0"
        rpy="0 0 0" />
      <geometry>
        <mesh
          filename="package://car_assem3/meshes/base_link.STL" />
      </geometry>
      <material
        name="">
        <color
          rgba="0.792156862745098 0.819607843137255 0.933333333333333 1" />
      </material>
    </visual>
    <collision>
      <origin
        xyz="0 0 0"
        rpy="0 0 0" />
      <geometry>
        <mesh
          filename="package://car_assem3/meshes/base_link.STL" />
      </geometry>
    </collision>
  </link>
  <link
    name="rca">
    <inertial>
      <origin
        xyz="0.0651933914576131 -0.035 0.0399152256624165"
        rpy="0 0 0" />
      <mass
        value="0.939491118430776" />
      <inertia
        ixx="0.00323160730926106"
        ixy="-3.27491033371768E-20"
        ixz="0.00244475217966051"
        iyy="0.00940297439326515"
        iyz="1.77807311598556E-20"
        izz="0.00652191556233996" />
    </inertial>
    <visual>
      <origin
        xyz="0 0 0"
        rpy="0 0 0" />
      <geometry>
        <mesh
          filename="package://car_assem3/meshes/rca.STL" />
      </geometry>
      <material
        name="">
        <color
          rgba="0.792156862745098 0.819607843137255 0.933333333333333 1" />
      </material>
    </visual>
    <collision>
      <origin
        xyz="0 0 0"
        rpy="0 0 0" />
      <geometry>
        <mesh
          filename="package://car_assem3/meshes/rca.STL" />
      </geometry>
    </collision>
  </link>
  <joint
    name="rca"
    type="revolute">
    <origin
      xyz="0.2 0.23 0.01"
      rpy="1.5708 0 0" />
    <parent
      link="base_link" />
    <child
      link="rca" />
    <axis
      xyz="0 1 0" />
    <limit
      lower="-0.7854"
      upper="0.7854"
      effort="0"
      velocity="0" />
  </joint>
  <link
    name="frw">
    <inertial>
      <origin
        xyz="0.037506268697997 -0.01 0.00391515814537721"
        rpy="0 0 0" />
      <mass
        value="2.18704107668104" />
      <inertia
        ixx="0.0115233152620549"
        ixy="-2.82470651275316E-20"
        ixz="-1.52490828967712E-19"
        iyy="0.00678683313572171"
        iyz="-1.01577779221512E-18"
        izz="0.00678683313572171" />
    </inertial>
    <visual>
      <origin
        xyz="0 0 0"
        rpy="0 0 0" />
      <geometry>
        <mesh
          filename="package://car_assem3/meshes/frw.STL" />
      </geometry>
      <material
        name="">
        <color
          rgba="0.792156862745098 0.819607843137255 0.933333333333333 1" />
      </material>
    </visual>
    <collision>
      <origin
        xyz="0 0 0"
        rpy="0 0 0" />
      <geometry>
        <mesh
          filename="package://car_assem3/meshes/frw.STL" />
      </geometry>
    </collision>
  </link>
  <joint
    name="frw"
    type="continuous">
    <origin
      xyz="0.17499 -0.025 -0.0039152"
      rpy="0 0 0" />
    <parent
      link="rca" />
    <child
      link="frw" />
    <axis
      xyz="1 0 0" />
  </joint>
  <link
    name="lca">
    <inertial>
      <origin
        xyz="0.0651933914576132 0.015 0.0399152256624163"
        rpy="0 0 0" />
      <mass
        value="0.939491118430776" />
      <inertia
        ixx="0.00323160730926106"
        ixy="-5.49540559275752E-19"
        ixz="0.0024447521796605"
        iyy="0.00940297439326516"
        iyz="3.6428717664769E-19"
        izz="0.00652191556233998" />
    </inertial>
    <visual>
      <origin
        xyz="0 0 0"
        rpy="0 0 0" />
      <geometry>
        <mesh
          filename="package://car_assem3/meshes/lca.STL" />
      </geometry>
      <material
        name="">
        <color
          rgba="0.792156862745098 0.819607843137255 0.933333333333333 1" />
      </material>
    </visual>
    <collision>
      <origin
        xyz="0 0 0"
        rpy="0 0 0" />
      <geometry>
        <mesh
          filename="package://car_assem3/meshes/lca.STL" />
      </geometry>
    </collision>
  </link>
  <joint
    name="lca"
    type="revolute">
    <origin
      xyz="-0.2 0.23 -0.01"
      rpy="-1.5708 0 3.1416" />
    <parent
      link="base_link" />
    <child
      link="lca" />
    <axis
      xyz="0 1 0" />
    <limit
      lower="-0.7854"
      upper="0.7854"
      effort="0"
      velocity="0" />
  </joint>
  <link
    name="flw">
    <inertial>
      <origin
        xyz="-0.0380224438486342 -0.00999999999999999 0.000455447960069105"
        rpy="0 0 0" />
      <mass
        value="2.18704107668104" />
      <inertia
        ixx="0.0115233152620549"
        ixy="-7.27840407871417E-20"
        ixz="6.06025576123426E-20"
        iyy="0.00678683313572171"
        iyz="5.75717706336907E-19"
        izz="0.00678683313572171" />
    </inertial>
    <visual>
      <origin
        xyz="0 0 0"
        rpy="0 0 0" />
      <geometry>
        <mesh
          filename="package://car_assem3/meshes/flw.STL" />
      </geometry>
      <material
        name="">
        <color
          rgba="0.792156862745098 0.819607843137255 0.933333333333333 1" />
      </material>
    </visual>
    <collision>
      <origin
        xyz="0 0 0"
        rpy="0 0 0" />
      <geometry>
        <mesh
          filename="package://car_assem3/meshes/flw.STL" />
      </geometry>
    </collision>
  </link>
  <joint
    name="flw"
    type="continuous">
    <origin
      xyz="0.174477556151366 0.00500000000000001 -0.000455447960068578"
      rpy="0 0 3.14159265358979" />
    <parent
      link="lca" />
    <child
      link="flw" />
    <axis
      xyz="1 0 0" />
  </joint>
  <link
    name="back axle">
    <inertial>
      <origin
        xyz="-1.11022302462516E-16 -0.01 0"
        rpy="0 0 0" />
      <mass
        value="2.00398223686155" />
      <inertia
        ixx="0.00075893987653666"
        ixy="8.60267837055149E-20"
        ixz="8.40123999184203E-19"
        iyy="0.12399586283278"
        iyz="-4.13590306276507E-22"
        izz="0.123990103246249" />
    </inertial>
    <visual>
      <origin
        xyz="0 0 0"
        rpy="0 0 0" />
      <geometry>
        <mesh
          filename="package://car_assem3/meshes/back axle.STL" />
      </geometry>
      <material
        name="">
        <color
          rgba="0.792156862745098 0.819607843137255 0.933333333333333 1" />
      </material>
    </visual>
    <collision>
      <origin
        xyz="0 0 0"
        rpy="0 0 0" />
      <geometry>
        <mesh
          filename="package://car_assem3/meshes/back axle.STL" />
      </geometry>
    </collision>
  </link>
  <joint
    name="back axle"
    type="fixed">
    <origin
      xyz="0 -0.27 -0.015"
      rpy="1.5707963267949 0 0" />
    <parent
      link="base_link" />
    <child
      link="back axle" />
    <axis
      xyz="0 0 0" />
  </joint>
  <link
    name="blw">
    <inertial>
      <origin
        xyz="-0.0374999999999999 -0.01 0"
        rpy="0 0 0" />
      <mass
        value="2.18704107668104" />
      <inertia
        ixx="0.0115233152620549"
        ixy="-1.38463478069984E-19"
        ixz="-9.3582047013588E-20"
        iyy="0.00678683313572171"
        iyz="-3.70576914423756E-19"
        izz="0.00678683313572171" />
    </inertial>
    <visual>
      <origin
        xyz="0 0 0"
        rpy="0 0 0" />
      <geometry>
        <mesh
          filename="package://car_assem3/meshes/blw.STL" />
      </geometry>
      <material
        name="">
        <color
          rgba="0.792156862745098 0.819607843137255 0.933333333333333 1" />
      </material>
    </visual>
    <collision>
      <origin
        xyz="0 0 0"
        rpy="0 0 0" />
      <geometry>
        <mesh
          filename="package://car_assem3/meshes/blw.STL" />
      </geometry>
    </collision>
  </link>
  <joint
    name="blw"
    type="continuous">
    <origin
      xyz="-0.375 0 0"
      rpy="0 0 0" />
    <parent
      link="back axle" />
    <child
      link="blw" />
    <axis
      xyz="1 0 0" />
  </joint>
  <link
    name="brw">
    <inertial>
      <origin
        xyz="0.0375 -0.01 -5.55111512312578E-17"
        rpy="0 0 0" />
      <mass
        value="2.18704107668104" />
      <inertia
        ixx="0.0115233152620549"
        ixy="-1.38463478069984E-19"
        ixz="-9.35820470135877E-20"
        iyy="0.00678683313572171"
        iyz="-3.70576914423756E-19"
        izz="0.00678683313572171" />
    </inertial>
    <visual>
      <origin
        xyz="0 0 0"
        rpy="0 0 0" />
      <geometry>
        <mesh
          filename="package://car_assem3/meshes/brw.STL" />
      </geometry>
      <material
        name="">
        <color
          rgba="0.792156862745098 0.819607843137255 0.933333333333333 1" />
      </material>
    </visual>
    <collision>
      <origin
        xyz="0 0 0"
        rpy="0 0 0" />
      <geometry>
        <mesh
          filename="package://car_assem3/meshes/brw.STL" />
      </geometry>
    </collision>
  </link>
  <joint
    name="brw"
    type="continuous">
    <origin
      xyz="0.375 0 0"
      rpy="0 0 0" />
    <parent
      link="back axle" />
    <child
      link="brw" />
    <axis
      xyz="1 0 0" />
  </joint>
  <link
    name="trailer body">
    <inertial>
      <origin
        xyz="1.40520811834791E-16 0.00530597354698728 0.438714794679746"
        rpy="0 0 0" />
      <mass
        value="7.71727875959474" />
      <inertia
        ixx="0.189109748166744"
        ixy="-2.92962081988012E-19"
        ixz="-2.12566061738858E-17"
        iyy="0.344210482149803"
        iyz="0.000844263187931334"
        izz="0.156272622704335" />
    </inertial>
    <visual>
      <origin
        xyz="0 0 0"
        rpy="0 0 0" />
      <geometry>
        <mesh
          filename="package://car_assem3/meshes/trailer body.STL" />
      </geometry>
      <material
        name="">
        <color
          rgba="0.792156862745098 0.819607843137255 0.933333333333333 1" />
      </material>
    </visual>
    <collision>
      <origin
        xyz="0 0 0"
        rpy="0 0 0" />
      <geometry>
        <mesh
          filename="package://car_assem3/meshes/trailer body.STL" />
      </geometry>
    </collision>
  </link>
  <joint
    name="trailer body"
    type="revolute">
    <origin
      xyz="0 -0.4 0.01"
      rpy="1.5708 0 0" />
    <parent
      link="base_link" />
    <child
      link="trailer body" />
    <axis
      xyz="0 1 0" />
    <limit
      lower="-0.69813"
      upper="0.69813"
      effort="0"
      velocity="0" />
  </joint>
  <link
    name="trailer axle">
    <inertial>
      <origin
        xyz="0.00452867662134583 -0.01 2.2788256931694E-05"
        rpy="0 0 0" />
      <mass
        value="2.00398223686155" />
      <inertia
        ixx="0.000758939876536661"
        ixy="-2.64697796016969E-20"
        ixz="8.46741444084627E-19"
        iyy="0.12399586283278"
        iyz="1.03397576569128E-20"
        izz="0.123990103246249" />
    </inertial>
    <visual>
      <origin
        xyz="0 0 0"
        rpy="0 0 0" />
      <geometry>
        <mesh
          filename="package://car_assem3/meshes/trailer axle.STL" />
      </geometry>
      <material
        name="">
        <color
          rgba="0.792156862745098 0.819607843137255 0.933333333333333 1" />
      </material>
    </visual>
    <collision>
      <origin
        xyz="0 0 0"
        rpy="0 0 0" />
      <geometry>
        <mesh
          filename="package://car_assem3/meshes/trailer axle.STL" />
      </geometry>
    </collision>
  </link>
  <joint
    name="trailer axle"
    type="fixed">
    <origin
      xyz="-0.00452867662134572 -0.025 0.449977211743068"
      rpy="0 0 0" />
    <parent
      link="trailer body" />
    <child
      link="trailer axle" />
    <axis
      xyz="0 0 0" />
  </joint>
  <link
    name="trw">
    <inertial>
      <origin
        xyz="0.0440593694188843 -0.01 -0.00373086267900002"
        rpy="0 0 0" />
      <mass
        value="2.18704107668104" />
      <inertia
        ixx="0.0115233152620549"
        ixy="-1.48222629081794E-19"
        ixz="6.77062093211532E-21"
        iyy="0.00678683313572171"
        iyz="-1.22422730657848E-19"
        izz="0.00678683313572171" />
    </inertial>
    <visual>
      <origin
        xyz="0 0 0"
        rpy="0 0 0" />
      <geometry>
        <mesh
          filename="package://car_assem3/meshes/trw.STL" />
      </geometry>
      <material
        name="">
        <color
          rgba="0.792156862745098 0.819607843137255 0.933333333333333 1" />
      </material>
    </visual>
    <collision>
      <origin
        xyz="0 0 0"
        rpy="0 0 0" />
      <geometry>
        <mesh
          filename="package://car_assem3/meshes/trw.STL" />
      </geometry>
    </collision>
  </link>
  <joint
    name="trw"
    type="continuous">
    <origin
      xyz="0.372969307202462 0 0.00375365093593172"
      rpy="0 0 0" />
    <parent
      link="trailer axle" />
    <child
      link="trw" />
    <axis
      xyz="1 0 0" />
  </joint>
  <link
    name="tlw">
    <inertial>
      <origin
        xyz="-0.0350020161761894 -0.01 0.00377643919286375"
        rpy="0 0 0" />
      <mass
        value="2.18704107668104" />
      <inertia
        ixx="0.0115233152620549"
        ixy="-3.79424736017388E-21"
        ixz="-7.12183166962454E-20"
        iyy="0.00678683313572171"
        iyz="4.46677530778635E-19"
        izz="0.00678683313572171" />
    </inertial>
    <visual>
      <origin
        xyz="0 0 0"
        rpy="0 0 0" />
      <geometry>
        <mesh
          filename="package://car_assem3/meshes/tlw.STL" />
      </geometry>
      <material
        name="">
        <color
          rgba="0.792156862745098 0.819607843137255 0.933333333333333 1" />
      </material>
    </visual>
    <collision>
      <origin
        xyz="0 0 0"
        rpy="0 0 0" />
      <geometry>
        <mesh
          filename="package://car_assem3/meshes/tlw.STL" />
      </geometry>
    </collision>
  </link>
  <joint
    name="tlw"
    type="continuous">
    <origin
      xyz="-0.372969307202465 0 -0.00375365093593194"
      rpy="0 0 0" />
    <parent
      link="trailer axle" />
    <child
      link="tlw" />
    <axis
      xyz="1 0 0" />
  </joint>
</robot>