<?xml version="1.0" encoding="utf-8"?>
<!-- This URDF was automatically created by SolidWorks to URDF Exporter! Originally created by Stephen Brawner (brawner@gmail.com) 
     Commit Version: 1.6.0-4-g7f85cfe  Build Version: 1.6.7995.38578
     For more information, please see http://wiki.ros.org/sw_urdf_exporter -->
<robot
  name="top assembly with gripper URDF attempt 7">
  <link
    name="base_link">
    <inertial>
      <origin
        xyz="-2.86460855991498E-19 -2.12756797100531E-17 -0.425995488565801"
        rpy="0 0 0" />
      <mass
        value="90.5491893240932" />
      <inertia
        ixx="3.48663798151639"
        ixy="2.67257961887655E-18"
        ixz="1.04271232501609E-17"
        iyy="3.48670868252581"
        iyz="-3.38870578284709E-16"
        izz="3.81582853495264" />
    </inertial>
    <visual>
      <origin
        xyz="0 0 0"
        rpy="0 0 0" />
      <geometry>
        <mesh
          filename="package://top assembly with gripper URDF attempt 7/meshes/base_link.STL" />
      </geometry>
      <material
        name="">
        <color
          rgba="0.792156862745098 0.819607843137255 0.933333333333333 1" />
      </material>
    </visual>
    <collision>
      <origin
        xyz="0 0 0"
        rpy="0 0 0" />
      <geometry>
        <mesh
          filename="package://top assembly with gripper URDF attempt 7/meshes/base_link.STL" />
      </geometry>
    </collision>
  </link>
  <link
    name="link_arm_1">
    <inertial>
      <origin
        xyz="0.0102112642270262 0.0397887357729738 0"
        rpy="0 0 0" />
      <mass
        value="0.616850275068085" />
      <inertia
        ixx="0.000758328898628989"
        ixy="-0.000117533258784041"
        ixz="-2.25875452601147E-20"
        iyy="0.000758328898628989"
        iyz="2.25875452601147E-20"
        izz="0.000745594953422872" />
    </inertial>
    <visual>
      <origin
        xyz="0 0 0"
        rpy="0 0 0" />
      <geometry>
        <mesh
          filename="package://top assembly with gripper URDF attempt 7/meshes/link_arm_1.STL" />
      </geometry>
      <material
        name="">
        <color
          rgba="0.792156862745098 0.819607843137255 0.933333333333333 1" />
      </material>
    </visual>
    <collision>
      <origin
        xyz="0 0 0"
        rpy="0 0 0" />
      <geometry>
        <mesh
          filename="package://top assembly with gripper URDF attempt 7/meshes/link_arm_1.STL" />
      </geometry>
    </collision>
  </link>
  <joint
    name="joint_arm_1"
    type="continuous">
    <origin
      xyz="0 0 0.01"
      rpy="1.5707963267949 0 0" />
    <parent
      link="base_link" />
    <child
      link="link_arm_1" />
    <axis
      xyz="0 1 0" />
  </joint>
  <link
    name="link_arm_2">
    <inertial>
      <origin
        xyz="-0.425 0.0479521392077196 -5.04698321809284E-18"
        rpy="0 0 0" />
      <mass
        value="6.00499439277567" />
      <inertia
        ixx="0.00644980256719211"
        ixy="-8.68208770935658E-18"
        ixz="1.35666243727304E-18"
        iyy="0.439844327950975"
        iyz="1.08332962219202E-18"
        izz="0.439921069814824" />
    </inertial>
    <visual>
      <origin
        xyz="0 0 0"
        rpy="0 0 0" />
      <geometry>
        <mesh
          filename="package://top assembly with gripper URDF attempt 7/meshes/link_arm_2.STL" />
      </geometry>
      <material
        name="">
        <color
          rgba="0.792156862745098 0.819607843137255 0.933333333333333 1" />
      </material>
    </visual>
    <collision>
      <origin
        xyz="0 0 0"
        rpy="0 0 0" />
      <geometry>
        <mesh
          filename="package://top assembly with gripper URDF attempt 7/meshes/link_arm_2.STL" />
      </geometry>
    </collision>
  </link>
  <joint
    name="joint_arm_2"
    type="revolute">
    <origin
      xyz="0.04995 0.0500000000000008 0"
      rpy="0 0 -1.5707963267949" />
    <parent
      link="link_arm_1" />
    <child
      link="link_arm_2" />
    <axis
      xyz="0 1 0" />
    <limit
      lower="-1.5708"
      upper="1.5708"
      effort="0"
      velocity="0" />
  </joint>
  <link
    name="link_arm_3">
    <inertial>
      <origin
        xyz="-0.37499896693226 -0.0499499434508651 1.40926562802143E-08"
        rpy="0 0 0" />
      <mass
        value="5.36884463480403" />
      <inertia
        ixx="0.00583223984122909"
        ixy="-0.00483062346048854"
        ixz="-1.96718551825591E-08"
        iyy="0.313371733808534"
        iyz="2.20564241042035E-08"
        izz="0.313475132379175" />
    </inertial>
    <visual>
      <origin
        xyz="0 0 0"
        rpy="0 0 0" />
      <geometry>
        <mesh
          filename="package://top assembly with gripper URDF attempt 7/meshes/link_arm_3.STL" />
      </geometry>
      <material
        name="">
        <color
          rgba="0.792156862745098 0.819607843137255 0.933333333333333 1" />
      </material>
    </visual>
    <collision>
      <origin
        xyz="0 0 0"
        rpy="0 0 0" />
      <geometry>
        <mesh
          filename="package://top assembly with gripper URDF attempt 7/meshes/link_arm_3.STL" />
      </geometry>
    </collision>
  </link>
  <joint
    name="joint_arm_3"
    type="continuous">
    <origin
      xyz="-0.85 0 0"
      rpy="-3.14159265358979 0 3.14159265358979" />
    <parent
      link="link_arm_2" />
    <child
      link="link_arm_3" />
    <axis
      xyz="0 1 0" />
  </joint>
  <link
    name="link_arm_4">
    <inertial>
      <origin
        xyz="0.0557979256916667 0.0449730992840096 3.2724099398948E-17"
        rpy="0 0 0" />
      <mass
        value="1.25302278742002" />
      <inertia
        ixx="0.00143510894590358"
        ixy="-0.000404675486049316"
        ixz="2.05699952076892E-19"
        iyy="0.00413540723242508"
        iyz="5.74154737412548E-20"
        izz="0.00415532866573722" />
    </inertial>
    <visual>
      <origin
        xyz="0 0 0"
        rpy="0 0 0" />
      <geometry>
        <mesh
          filename="package://top assembly with gripper URDF attempt 7/meshes/link_arm_4.STL" />
      </geometry>
      <material
        name="">
        <color
          rgba="0.792156862745098 0.819607843137255 0.933333333333333 1" />
      </material>
    </visual>
    <collision>
      <origin
        xyz="0 0 0"
        rpy="0 0 0" />
      <geometry>
        <mesh
          filename="package://top assembly with gripper URDF attempt 7/meshes/link_arm_4.STL" />
      </geometry>
    </collision>
  </link>
  <joint
    name="joint_arm_4"
    type="continuous">
    <origin
      xyz="-0.75 -0.09995 0"
      rpy="3.14159265358979 0 0" />
    <parent
      link="link_arm_3" />
    <child
      link="link_arm_4" />
    <axis
      xyz="0 1 0" />
  </joint>
  <link
    name="link_arm_5">
    <inertial>
      <origin
        xyz="0.0102112642270262 -0.0397887357729738 -1.38777878078145E-17"
        rpy="0 0 0" />
      <mass
        value="0.616850275068085" />
      <inertia
        ixx="0.000758328898628989"
        ixy="0.000117533258784041"
        ixz="2.25875452601147E-20"
        iyy="0.000758328898628989"
        iyz="4.43552749145502E-20"
        izz="0.000745594953422872" />
    </inertial>
    <visual>
      <origin
        xyz="0 0 0"
        rpy="0 0 0" />
      <geometry>
        <mesh
          filename="package://top assembly with gripper URDF attempt 7/meshes/link_arm_5.STL" />
      </geometry>
      <material
        name="">
        <color
          rgba="0.792156862745098 0.819607843137255 0.933333333333333 1" />
      </material>
    </visual>
    <collision>
      <origin
        xyz="0 0 0"
        rpy="0 0 0" />
      <geometry>
        <mesh
          filename="package://top assembly with gripper URDF attempt 7/meshes/link_arm_5.STL" />
      </geometry>
    </collision>
  </link>
  <joint
    name="joint_arm_5"
    type="revolute">
    <origin
      xyz="0.15 0.05 0"
      rpy="1.5707963267949 -1.5707963267949 0" />
    <parent
      link="link_arm_4" />
    <child
      link="link_arm_5" />
    <axis
      xyz="0 1 0" />
    <limit
      lower="0"
      upper="3.1416"
      effort="0"
      velocity="0" />
  </joint>
  <link
    name="link_gripper_base">
    <inertial>
      <origin
        xyz="-5.55111512312578E-17 0.085172063756944 0"
        rpy="0 0 0" />
      <mass
        value="1.54618356156085" />
      <inertia
        ixx="0.00394696586696142"
        ixy="1.29273910760298E-19"
        ixz="-3.8525989986861E-19"
        iyy="0.00418542418839053"
        iyz="1.59642784896773E-19"
        izz="0.00580996586696143" />
    </inertial>
    <visual>
      <origin
        xyz="0 0 0"
        rpy="0 0 0" />
      <geometry>
        <mesh
          filename="package://top assembly with gripper URDF attempt 7/meshes/link_gripper_base.STL" />
      </geometry>
      <material
        name="">
        <color
          rgba="0.792156862745098 0.819607843137255 0.933333333333333 1" />
      </material>
    </visual>
    <collision>
      <origin
        xyz="0 0 0"
        rpy="0 0 0" />
      <geometry>
        <mesh
          filename="package://top assembly with gripper URDF attempt 7/meshes/link_gripper_base.STL" />
      </geometry>
    </collision>
  </link>
  <joint
    name="joint_gripper_base"
    type="continuous">
    <origin
      xyz="0.0500000000000001 -0.05 0"
      rpy="3.14159265358979 0 1.5707963267949" />
    <parent
      link="link_arm_5" />
    <child
      link="link_gripper_base" />
    <axis
      xyz="0 1 0" />
  </joint>
  <link
    name="link_gripper_gear">
    <inertial>
      <origin
        xyz="-4.16333634234434E-17 -0.005 0"
        rpy="0 0 0" />
      <mass
        value="0.00510508806208342" />
      <inertia
        ixx="3.74495843015815E-07"
        ixy="1.39004156150461E-22"
        ixz="3.11019910319938E-22"
        iyy="6.63906884996906E-07"
        iyz="1.19690917793767E-23"
        izz="3.74495843015815E-07" />
    </inertial>
    <visual>
      <origin
        xyz="0 0 0"
        rpy="0 0 0" />
      <geometry>
        <mesh
          filename="package://top assembly with gripper URDF attempt 7/meshes/link_gripper_gear.STL" />
      </geometry>
      <material
        name="">
        <color
          rgba="0.792156862745098 0.819607843137255 0.933333333333333 1" />
      </material>
    </visual>
    <collision>
      <origin
        xyz="0 0 0"
        rpy="0 0 0" />
      <geometry>
        <mesh
          filename="package://top assembly with gripper URDF attempt 7/meshes/link_gripper_gear.STL" />
      </geometry>
    </collision>
  </link>
  <joint
    name="joint_gripper_gear"
    type="continuous">
    <origin
      xyz="0 0.15 0"
      rpy="0 1.3304373783365 3.14159265358979" />
    <parent
      link="link_gripper_base" />
    <child
      link="link_gripper_gear" />
    <axis
      xyz="0 1 0" />
  </joint>
  <link
    name="link_gripper_pad1">
    <inertial>
      <origin
        xyz="-0.0177631578947368 0.0426973684210525 -0.0651973684210526"
        rpy="0 0 0" />
      <mass
        value="0.114" />
      <inertia
        ixx="0.000304591118421053"
        ixy="3.67253289473684E-05"
        ixz="-1.85032894736845E-06"
        iyy="9.59751644736843E-05"
        iyz="-3.25731907894737E-05"
        izz="0.000302275164473684" />
    </inertial>
    <visual>
      <origin
        xyz="0 0 0"
        rpy="0 0 0" />
      <geometry>
        <mesh
          filename="package://top assembly with gripper URDF attempt 7/meshes/link_gripper_pad1.STL" />
      </geometry>
      <material
        name="">
        <color
          rgba="0.792156862745098 0.819607843137255 0.933333333333333 1" />
      </material>
    </visual>
    <collision>
      <origin
        xyz="0 0 0"
        rpy="0 0 0" />
      <geometry>
        <mesh
          filename="package://top assembly with gripper URDF attempt 7/meshes/link_gripper_pad1.STL" />
      </geometry>
    </collision>
  </link>
  <joint
    name="joint_gripper_pad1"
    type="prismatic">
    <origin
      xyz="0 0.15 -0.025"
      rpy="0 1.5708 0" />
    <parent
      link="link_gripper_base" />
    <child
      link="link_gripper_pad1" />
    <axis
      xyz="0 0 1" />
    <limit
      lower="0"
      upper="0.055"
      effort="0"
      velocity="0" />
  </joint>
  <link
    name="link_gripper_pad2">
    <inertial>
      <origin
        xyz="-0.0177631578947368 0.0426973684210526 -0.0651973684210526"
        rpy="0 0 0" />
      <mass
        value="0.114" />
      <inertia
        ixx="0.000304591118421053"
        ixy="3.67253289473683E-05"
        ixz="-1.85032894736847E-06"
        iyy="9.59751644736843E-05"
        iyz="-3.25731907894737E-05"
        izz="0.000302275164473685" />
    </inertial>
    <visual>
      <origin
        xyz="0 0 0"
        rpy="0 0 0" />
      <geometry>
        <mesh
          filename="package://top assembly with gripper URDF attempt 7/meshes/link_gripper_pad2.STL" />
      </geometry>
      <material
        name="">
        <color
          rgba="0.792156862745098 0.819607843137255 0.933333333333333 1" />
      </material>
    </visual>
    <collision>
      <origin
        xyz="0 0 0"
        rpy="0 0 0" />
      <geometry>
        <mesh
          filename="package://top assembly with gripper URDF attempt 7/meshes/link_gripper_pad2.STL" />
      </geometry>
    </collision>
  </link>
  <joint
    name="joint_gripper_pad2"
    type="prismatic">
    <origin
      xyz="0 0.15 0.025"
      rpy="0 -1.5708 0" />
    <parent
      link="link_gripper_base" />
    <child
      link="link_gripper_pad2" />
    <axis
      xyz="0 0 1" />
    <limit
      lower="0"
      upper="0.055"
      effort="0"
      velocity="0" />
  </joint>
  <link
    name="link_slot1">
    <inertial>
      <origin
        xyz="7.85919950301768E-17 0.015936952714536 0.107644483362522"
        rpy="0 0 0" />
      <mass
        value="0.570999999999999" />
      <inertia
        ixx="0.010628303477087"
        ixy="1.96870260601874E-18"
        ixz="3.23867140695356E-19"
        iyy="0.00329411724678925"
        iyz="-0.000203435201401051"
        izz="0.00847389039696439" />
    </inertial>
    <visual>
      <origin
        xyz="0 0 0"
        rpy="0 0 0" />
      <geometry>
        <mesh
          filename="package://top assembly with gripper URDF attempt 7/meshes/link_slot1.STL" />
      </geometry>
      <material
        name="">
        <color
          rgba="0.792156862745098 0.819607843137255 0.933333333333333 1" />
      </material>
    </visual>
    <collision>
      <origin
        xyz="0 0 0"
        rpy="0 0 0" />
      <geometry>
        <mesh
          filename="package://top assembly with gripper URDF attempt 7/meshes/link_slot1.STL" />
      </geometry>
    </collision>
  </link>
  <joint
    name="joint_slot1"
    type="fixed">
    <origin
      xyz="0 -0.064952 -0.1525"
      rpy="1.5708 0 0" />
    <parent
      link="base_link" />
    <child
      link="link_slot1" />
    <axis
      xyz="0 0 0" />
  </joint>
  <link
    name="link_slot2">
    <inertial>
      <origin
        xyz="5.89805981832114E-17 0.0159369527145362 0.107644483362522"
        rpy="0 0 0" />
      <mass
        value="0.570999999999998" />
      <inertia
        ixx="0.010628303477087"
        ixy="7.45388993583784E-19"
        ixz="-2.38524477946811E-18"
        iyy="0.00329411724678925"
        iyz="-0.000203435201401053"
        izz="0.00847389039696439" />
    </inertial>
    <visual>
      <origin
        xyz="0 0 0"
        rpy="0 0 0" />
      <geometry>
        <mesh
          filename="package://top assembly with gripper URDF attempt 7/meshes/link_slot2.STL" />
      </geometry>
      <material
        name="">
        <color
          rgba="0.792156862745098 0.819607843137255 0.933333333333333 1" />
      </material>
    </visual>
    <collision>
      <origin
        xyz="0 0 0"
        rpy="0 0 0" />
      <geometry>
        <mesh
          filename="package://top assembly with gripper URDF attempt 7/meshes/link_slot2.STL" />
      </geometry>
    </collision>
  </link>
  <joint
    name="joint_slot2"
    type="fixed">
    <origin
      xyz="-0.05625 -0.032476 -0.1525"
      rpy="1.5708 0 -1.0472" />
    <parent
      link="base_link" />
    <child
      link="link_slot2" />
    <axis
      xyz="0 0 0" />
  </joint>
  <link
    name="link_slot3">
    <inertial>
      <origin
        xyz="3.12250225675825E-17 0.0159369527145359 0.107644483362522"
        rpy="0 0 0" />
      <mass
        value="0.570999999999999" />
      <inertia
        ixx="0.010628303477087"
        ixy="1.32814766129474E-18"
        ixz="8.67361737988404E-19"
        iyy="0.00329411724678926"
        iyz="-0.00020343520140105"
        izz="0.00847389039696441" />
    </inertial>
    <visual>
      <origin
        xyz="0 0 0"
        rpy="0 0 0" />
      <geometry>
        <mesh
          filename="package://top assembly with gripper URDF attempt 7/meshes/link_slot3.STL" />
      </geometry>
      <material
        name="">
        <color
          rgba="0.792156862745098 0.819607843137255 0.933333333333333 1" />
      </material>
    </visual>
    <collision>
      <origin
        xyz="0 0 0"
        rpy="0 0 0" />
      <geometry>
        <mesh
          filename="package://top assembly with gripper URDF attempt 7/meshes/link_slot3.STL" />
      </geometry>
    </collision>
  </link>
  <joint
    name="joint_slot3"
    type="fixed">
    <origin
      xyz="-0.05625 0.032476 -0.1525"
      rpy="1.5708 0 -2.0944" />
    <parent
      link="base_link" />
    <child
      link="link_slot3" />
    <axis
      xyz="0 0 0" />
  </joint>
  <link
    name="link_slot4">
    <inertial>
      <origin
        xyz="1.28344400435297E-15 0.015936952714536 0.107644483362522"
        rpy="0 0 0" />
      <mass
        value="0.570999999999999" />
      <inertia
        ixx="0.010628303477087"
        ixy="1.1259963310743E-18"
        ixz="-1.51849859495627E-17"
        iyy="0.00329411724678926"
        iyz="-0.000203435201401053"
        izz="0.0084738903969644" />
    </inertial>
    <visual>
      <origin
        xyz="0 0 0"
        rpy="0 0 0" />
      <geometry>
        <mesh
          filename="package://top assembly with gripper URDF attempt 7/meshes/link_slot4.STL" />
      </geometry>
      <material
        name="">
        <color
          rgba="0.792156862745098 0.819607843137255 0.933333333333333 1" />
      </material>
    </visual>
    <collision>
      <origin
        xyz="0 0 0"
        rpy="0 0 0" />
      <geometry>
        <mesh
          filename="package://top assembly with gripper URDF attempt 7/meshes/link_slot4.STL" />
      </geometry>
    </collision>
  </link>
  <joint
    name="joint_slot4"
    type="fixed">
    <origin
      xyz="0 0.064952 -0.1525"
      rpy="1.5708 0 3.1416" />
    <parent
      link="base_link" />
    <child
      link="link_slot4" />
    <axis
      xyz="0 0 0" />
  </joint>
  <link
    name="link_slot5">
    <inertial>
      <origin
        xyz="7.28583859910259E-17 0.015936952714536 0.107644483362522"
        rpy="0 0 0" />
      <mass
        value="0.570999999999999" />
      <inertia
        ixx="0.010628303477087"
        ixy="1.73472347597681E-18"
        ixz="2.16840434497101E-19"
        iyy="0.00329411724678925"
        iyz="-0.000203435201401053"
        izz="0.00847389039696439" />
    </inertial>
    <visual>
      <origin
        xyz="0 0 0"
        rpy="0 0 0" />
      <geometry>
        <mesh
          filename="package://top assembly with gripper URDF attempt 7/meshes/link_slot5.STL" />
      </geometry>
      <material
        name="">
        <color
          rgba="0.792156862745098 0.819607843137255 0.933333333333333 1" />
      </material>
    </visual>
    <collision>
      <origin
        xyz="0 0 0"
        rpy="0 0 0" />
      <geometry>
        <mesh
          filename="package://top assembly with gripper URDF attempt 7/meshes/link_slot5.STL" />
      </geometry>
    </collision>
  </link>
  <joint
    name="joint_slot5"
    type="fixed">
    <origin
      xyz="0.05625 0.032476 -0.1525"
      rpy="1.5708 0 2.0944" />
    <parent
      link="base_link" />
    <child
      link="link_slot5" />
    <axis
      xyz="0 0 0" />
  </joint>
  <link
    name="link_slot6">
    <inertial>
      <origin
        xyz="-4.5102810375397E-17 0.015936952714536 0.107644483362522"
        rpy="0 0 0" />
      <mass
        value="0.570999999999998" />
      <inertia
        ixx="0.010628303477087"
        ixy="3.11708124589583E-19"
        ixz="6.50521303491303E-19"
        iyy="0.00329411724678925"
        iyz="-0.000203435201401053"
        izz="0.00847389039696437" />
    </inertial>
    <visual>
      <origin
        xyz="0 0 0"
        rpy="0 0 0" />
      <geometry>
        <mesh
          filename="package://top assembly with gripper URDF attempt 7/meshes/link_slot6.STL" />
      </geometry>
      <material
        name="">
        <color
          rgba="0.792156862745098 0.819607843137255 0.933333333333333 1" />
      </material>
    </visual>
    <collision>
      <origin
        xyz="0 0 0"
        rpy="0 0 0" />
      <geometry>
        <mesh
          filename="package://top assembly with gripper URDF attempt 7/meshes/link_slot6.STL" />
      </geometry>
    </collision>
  </link>
  <joint
    name="joint_slot6"
    type="fixed">
    <origin
      xyz="0.05625 -0.032476 -0.1525"
      rpy="1.5708 0 1.0472" />
    <parent
      link="base_link" />
    <child
      link="link_slot6" />
    <axis
      xyz="0 0 0" />
  </joint>
  <link
    name="link_axle">
    <inertial>
      <origin
        xyz="4.82234097890664E-17 0.0187933133528533 -1.71388006119302E-16"
        rpy="0 0 0" />
      <mass
        value="1.62717919613712" />
      <inertia
        ixx="0.00105705357324475"
        ixy="-6.50998919450591E-20"
        ixz="2.62672673099725E-19"
        iyy="0.0268955742127174"
        iyz="3.69271246367438E-21"
        izz="0.0271686786600347" />
    </inertial>
    <visual>
      <origin
        xyz="0 0 0"
        rpy="0 0 0" />
      <geometry>
        <mesh
          filename="package://top assembly with gripper URDF attempt 7/meshes/link_axle.STL" />
      </geometry>
      <material
        name="">
        <color
          rgba="0.792156862745098 0.819607843137255 0.933333333333333 1" />
      </material>
    </visual>
    <collision>
      <origin
        xyz="0 0 0"
        rpy="0 0 0" />
      <geometry>
        <mesh
          filename="package://top assembly with gripper URDF attempt 7/meshes/link_axle.STL" />
      </geometry>
    </collision>
  </link>
  <joint
    name="joint_axle"
    type="fixed">
    <origin
      xyz="0 0 -0.66"
      rpy="1.5708 0 0" />
    <parent
      link="base_link" />
    <child
      link="link_axle" />
    <axis
      xyz="0 0 0" />
  </joint>
  <link
    name="link_drivewheel_right">
    <inertial>
      <origin
        xyz="-1.22124532708767E-15 2.1094237467878E-15 0.0150000000000001"
        rpy="0 0 0" />
      <mass
        value="0.206756066514378" />
      <inertia
        ixx="0.000155743535413241"
        ixy="-2.71050543121376E-20"
        ixz="9.59516819398126E-20"
        iyy="0.000155743535413241"
        iyz="-2.20090563521761E-19"
        izz="0.000280473660849326" />
    </inertial>
    <visual>
      <origin
        xyz="0 0 0"
        rpy="0 0 0" />
      <geometry>
        <mesh
          filename="package://top assembly with gripper URDF attempt 7/meshes/link_drivewheel_right.STL" />
      </geometry>
      <material
        name="">
        <color
          rgba="0.792156862745098 0.819607843137255 0.933333333333333 1" />
      </material>
    </visual>
    <collision>
      <origin
        xyz="0 0 0"
        rpy="0 0 0" />
      <geometry>
        <mesh
          filename="package://top assembly with gripper URDF attempt 7/meshes/link_drivewheel_right.STL" />
      </geometry>
    </collision>
  </link>
  <joint
    name="joint_drivewheel_right"
    type="continuous">
    <origin
      xyz="-0.27 0 0"
      rpy="-1.5707963267949 -0.468354047175859 1.5707963267949" />
    <parent
      link="link_axle" />
    <child
      link="link_drivewheel_right" />
    <axis
      xyz="0 0 1" />
  </joint>
  <link
    name="link_drivewheel_left">
    <inertial>
      <origin
        xyz="2.22044604925031E-16 1.11022302462516E-16 -0.0150000000000002"
        rpy="0 0 0" />
      <mass
        value="0.206756066514379" />
      <inertia
        ixx="0.000155743535413241"
        ixy="-6.7762635780344E-21"
        ixz="-1.27691993307046E-19"
        iyy="0.000155743535413241"
        iyz="-5.86209497915386E-20"
        izz="0.000280473660849326" />
    </inertial>
    <visual>
      <origin
        xyz="0 0 0"
        rpy="0 0 0" />
      <geometry>
        <mesh
          filename="package://top assembly with gripper URDF attempt 7/meshes/link_drivewheel_left.STL" />
      </geometry>
      <material
        name="">
        <color
          rgba="0.792156862745098 0.819607843137255 0.933333333333333 1" />
      </material>
    </visual>
    <collision>
      <origin
        xyz="0 0 0"
        rpy="0 0 0" />
      <geometry>
        <mesh
          filename="package://top assembly with gripper URDF attempt 7/meshes/link_drivewheel_left.STL" />
      </geometry>
    </collision>
  </link>
  <joint
    name="joint_drivewheel_left"
    type="continuous">
    <origin
      xyz="0.27 0 0"
      rpy="-1.5707963267949 -0.928545261457666 1.5707963267949" />
    <parent
      link="link_axle" />
    <child
      link="link_drivewheel_left" />
    <axis
      xyz="0 0 1" />
  </joint>
  <link
    name="link_swivel_front">
    <inertial>
      <origin
        xyz="0.00751421605065076 -0.0638265063331358 0"
        rpy="0 0 0" />
      <mass
        value="0.0232231111520553" />
      <inertia
        ixx="1.33246387076922E-05"
        ixy="-2.46162177312807E-06"
        ixz="-1.56492876976418E-22"
        iyy="5.36089786833522E-06"
        iyz="-2.29222280377614E-22"
        izz="1.74288397902587E-05" />
    </inertial>
    <visual>
      <origin
        xyz="0 0 0"
        rpy="0 0 0" />
      <geometry>
        <mesh
          filename="package://top assembly with gripper URDF attempt 7/meshes/link_swivel_front.STL" />
      </geometry>
      <material
        name="">
        <color
          rgba="0.792156862745098 0.819607843137255 0.933333333333333 1" />
      </material>
    </visual>
    <collision>
      <origin
        xyz="0 0 0"
        rpy="0 0 0" />
      <geometry>
        <mesh
          filename="package://top assembly with gripper URDF attempt 7/meshes/link_swivel_front.STL" />
      </geometry>
    </collision>
  </link>
  <joint
    name="joint_swivel_front"
    type="continuous">
    <origin
      xyz="0 -0.25983 -0.595"
      rpy="1.5708 0 0" />
    <parent
      link="base_link" />
    <child
      link="link_swivel_front" />
    <axis
      xyz="0 1 0" />
  </joint>
  <link
    name="link_swivelwheel_front">
    <inertial>
      <origin
        xyz="-1.94289029309402E-16 1.99840144432528E-15 -6.42954469774777E-18"
        rpy="0 0 0" />
      <mass
        value="0.104284859690789" />
      <inertia
        ixx="4.94884093335827E-05"
        ixy="-1.60936259978317E-20"
        ixz="-2.84984916370238E-21"
        iyy="4.94884093335827E-05"
        iyz="2.79656841993324E-21"
        izz="8.33340897135471E-05" />
    </inertial>
    <visual>
      <origin
        xyz="0 0 0"
        rpy="0 0 0" />
      <geometry>
        <mesh
          filename="package://top assembly with gripper URDF attempt 7/meshes/link_swivelwheel_front.STL" />
      </geometry>
      <material
        name="">
        <color
          rgba="0.792156862745098 0.819607843137255 0.933333333333333 1" />
      </material>
    </visual>
    <collision>
      <origin
        xyz="0 0 0"
        rpy="0 0 0" />
      <geometry>
        <mesh
          filename="package://top assembly with gripper URDF attempt 7/meshes/link_swivelwheel_front.STL" />
      </geometry>
    </collision>
  </link>
  <joint
    name="joint_swivelwheel_front"
    type="continuous">
    <origin
      xyz="0 -0.0775 0"
      rpy="-1.5707963267949 -1.3498896571676 1.5707963267949" />
    <parent
      link="link_swivel_front" />
    <child
      link="link_swivelwheel_front" />
    <axis
      xyz="0 0 1" />
  </joint>
  <link
    name="link_swivel_back">
    <inertial>
      <origin
        xyz="0.00751421605065047 -0.0638265063331358 5.55111512312578E-17"
        rpy="0 0 0" />
      <mass
        value="0.0232231111520553" />
      <inertia
        ixx="1.33246387076922E-05"
        ixy="-2.46162177312807E-06"
        ixz="1.76922682333176E-21"
        iyy="5.36089786833521E-06"
        iyz="1.83930448928181E-20"
        izz="1.74288397902587E-05" />
    </inertial>
    <visual>
      <origin
        xyz="0 0 0"
        rpy="0 0 0" />
      <geometry>
        <mesh
          filename="package://top assembly with gripper URDF attempt 7/meshes/link_swivel_back.STL" />
      </geometry>
      <material
        name="">
        <color
          rgba="0.792156862745098 0.819607843137255 0.933333333333333 1" />
      </material>
    </visual>
    <collision>
      <origin
        xyz="0 0 0"
        rpy="0 0 0" />
      <geometry>
        <mesh
          filename="package://top assembly with gripper URDF attempt 7/meshes/link_swivel_back.STL" />
      </geometry>
    </collision>
  </link>
  <joint
    name="joint_swivel_back"
    type="continuous">
    <origin
      xyz="0 0.25982621214848 -0.595"
      rpy="1.5707963267949 0 3.14159265358979" />
    <parent
      link="base_link" />
    <child
      link="link_swivel_back" />
    <axis
      xyz="0 1 0" />
  </joint>
  <link
    name="link_swivelwheel_back">
    <inertial>
      <origin
        xyz="0 -3.60822483003176E-16 1.85786483105861E-16"
        rpy="0 0 0" />
      <mass
        value="0.104284859690789" />
      <inertia
        ixx="4.94884093335827E-05"
        ixy="-1.6940658945086E-20"
        ixz="1.7587762524484E-21"
        iyy="4.94884093335827E-05"
        iyz="1.4852372018181E-21"
        izz="8.33340897135471E-05" />
    </inertial>
    <visual>
      <origin
        xyz="0 0 0"
        rpy="0 0 0" />
      <geometry>
        <mesh
          filename="package://top assembly with gripper URDF attempt 7/meshes/link_swivelwheel_back.STL" />
      </geometry>
      <material
        name="">
        <color
          rgba="0.792156862745098 0.819607843137255 0.933333333333333 1" />
      </material>
    </visual>
    <collision>
      <origin
        xyz="0 0 0"
        rpy="0 0 0" />
      <geometry>
        <mesh
          filename="package://top assembly with gripper URDF attempt 7/meshes/link_swivelwheel_back.STL" />
      </geometry>
    </collision>
  </link>
  <joint
    name="joint_swivelwheel_back"
    type="continuous">
    <origin
      xyz="0 -0.0775 0"
      rpy="-1.5707963267949 0.679011267521338 1.5707963267949" />
    <parent
      link="link_swivel_back" />
    <child
      link="link_swivelwheel_back" />
    <axis
      xyz="0 0 1" />
  </joint>
</robot>