<?xml version="1.0" encoding="utf-8"?>
<!-- This URDF was automatically created by SolidWorks to URDF Exporter! Originally created by Stephen Brawner (brawner@gmail.com) 
     Commit Version: 1.6.0-4-g7f85cfe  Build Version: 1.6.7995.38578
     For more information, please see http://wiki.ros.org/sw_urdf_exporter -->
<robot
  name="terp2">
  <link
    name="base_link">
    <inertial>
      <origin
        xyz="-2.08345565981191E-18 -3.46674454072399E-17 0.2"
        rpy="0 0 0" />
      <mass
        value="300.0" />
      <inertia
        ixx="14.0"
        ixy="-4.33680868994202E-18"
        ixz="1.11672823766007E-17"
        iyy="14.0"
        iyz="-1.90633701299994E-16"
        izz="8.0" />
    </inertial>
    <visual>
      <origin
        xyz="0 0 0"
        rpy="0 0 0" />
      <geometry>
        <mesh
          filename="package://terp2/meshes/base_link.STL" />
      </geometry>
      <material
        name="">
        <color
          rgba="1 1 1 1" />
      </material>
    </visual>
    <collision>
      <origin
        xyz="0 0 0"
        rpy="0 0 0" />
      <geometry>
        <mesh
          filename="package://terp2/meshes/base_link.STL" />
      </geometry>
    </collision>
  </link>
  <link name="imu_link"/>
  <joint name="joint_imu" type="fixed">
    <parent link="base_link"/>
    <child  link="imu_link"/>
  </joint>
  <gazebo reference="imu_link">
    <sensor name="terp2_imu" type="imu">
      <update_rate>100.0</update_rate>
      <always_on>true</always_on>
      <plugin name="imu_pub" filename="libgazebo_ros_imu_sensor.so">
        <ros>
          <remapping>~/out:=imu</remapping>   <!-- publishes /imu -->
        </ros>
        <frame_name>imu_link</frame_name>
      </plugin>
    </sensor>
  </gazebo>
  <link
    name="link_arm_1">
    <inertial>
      <origin
        xyz="0.0102112642270262 0.0497887357729738 0.01"
        rpy="0 0 0" />
      <mass
        value="1.66549574268383" />
      <inertia
        ixx="0.00204748802629827"
        ixy="-0.00031733979871691"
        ixz="-6.09863722023096E-20"
        iyy="0.00204748802629827"
        iyz="6.09863722023096E-20"
        izz="0.00201310637424175" />
    </inertial>
    <visual>
      <origin
        xyz="0 0 0"
        rpy="0 0 0" />
      <geometry>
        <mesh
          filename="package://terp2/meshes/link_arm_1.STL" />
      </geometry>
      <material
        name="">
        <color
          rgba="0.898039215686275 0.917647058823529 0.929411764705882 1" />
      </material>
    </visual>
    <collision>
      <origin
        xyz="0 0 0"
        rpy="0 0 0" />
      <geometry>
        <mesh
          filename="package://terp2/meshes/link_arm_1.STL" />
      </geometry>
    </collision>
  </link>
  <joint
    name="joint_arm_1"
    type="continuous">
    <origin
      xyz="0 0.01 0"
      rpy="1.5707963267949 0 0" />
    <parent
      link="base_link" />
    <child
      link="link_arm_1" />
    <axis
      xyz="0 1 0" />
  </joint>
  <link
    name="link_arm_2">
    <inertial>
      <origin
        xyz="0.425 0.0479521392077195 1.25522866292093E-16"
        rpy="0 0 0" />
      <mass
        value="16.2134848604943" />
      <inertia
        ixx="0.0174144669314187"
        ixy="-2.44799678935561E-17"
        ixz="-2.86226911134673E-16"
        iyy="1.18757968546763"
        iyz="1.60167941441752E-18"
        izz="1.18778688850003" />
    </inertial>
    <visual>
      <origin
        xyz="0 0 0"
        rpy="0 0 0" />
      <geometry>
        <mesh
          filename="package://terp2/meshes/link_arm_2.STL" />
      </geometry>
      <material
        name="">
        <color
          rgba="0.898039215686275 0.917647058823529 0.929411764705882 1" />
      </material>
    </visual>
    <collision>
      <origin
        xyz="0 0 0"
        rpy="0 0 0" />
      <geometry>
        <mesh
          filename="package://terp2/meshes/link_arm_2.STL" />
      </geometry>
    </collision>
  </link>
  <joint
    name="joint_arm_2"
    type="continuous">
    <origin
      xyz="0.04995 0.06 0.01"
      rpy="3.14159265358979 0 1.5707963267949" />
    <parent
      link="link_arm_1" />
    <child
      link="link_arm_2" />
    <axis
      xyz="0 1 0" />
  </joint>
  <link
    name="link_arm_3">
    <inertial>
      <origin
        xyz="0.375001033067741 0.0499500565491348 1.40926564518826E-08"
        rpy="0 0 0" />
      <mass
        value="14.4958805139709" />
      <inertia
        ixx="0.0157470475713186"
        ixy="-0.013042683343319"
        ixz="-5.31140089477955E-08"
        iyy="0.846103681283042"
        iyz="5.95523450835168E-08"
        izz="0.846382857423772" />
    </inertial>
    <visual>
      <origin
        xyz="0 0 0"
        rpy="0 0 0" />
      <geometry>
        <mesh
          filename="package://terp2/meshes/link_arm_3.STL" />
      </geometry>
      <material
        name="">
        <color
          rgba="0.898039215686275 0.917647058823529 0.929411764705882 1" />
      </material>
    </visual>
    <collision>
      <origin
        xyz="0 0 0"
        rpy="0 0 0" />
      <geometry>
        <mesh
          filename="package://terp2/meshes/link_arm_3.STL" />
      </geometry>
    </collision>
  </link>
  <joint
    name="joint_arm_3"
    type="continuous">
    <origin
      xyz="0.85 0 0"
      rpy="0 0 3.14159265358979" />
    <parent
      link="link_arm_2" />
    <child
      link="link_arm_3" />
    <axis
      xyz="0 1 0" />
  </joint>
  <link
    name="link_arm_4">
    <inertial>
      <origin
        xyz="0.0557979256916667 0.0449730992840096 -1.62569094709651E-16"
        rpy="0 0 0" />
      <mass
        value="3.38316152603405" />
      <inertia
        ixx="0.00387479415393967"
        ixy="-0.00109262381233315"
        ixz="5.87434023821623E-20"
        iyy="0.0111655995275477"
        iyz="6.50336489749628E-20"
        izz="0.0112193873974905" />
    </inertial>
    <visual>
      <origin
        xyz="0 0 0"
        rpy="0 0 0" />
      <geometry>
        <mesh
          filename="package://terp2/meshes/link_arm_4.STL" />
      </geometry>
      <material
        name="">
        <color
          rgba="0.898039215686275 0.917647058823529 0.929411764705882 1" />
      </material>
    </visual>
    <collision>
      <origin
        xyz="0 0 0"
        rpy="0 0 0" />
      <geometry>
        <mesh
          filename="package://terp2/meshes/link_arm_4.STL" />
      </geometry>
    </collision>
  </link>
  <joint
    name="joint_arm_4"
    type="continuous">
    <origin
      xyz="0.75 0.09995 0"
      rpy="3.14159265358979 0 3.14159265358979" />
    <parent
      link="link_arm_3" />
    <child
      link="link_arm_4" />
    <axis
      xyz="0 1 0" />
  </joint>
  <link
    name="link_arm_5">
    <inertial>
      <origin
        xyz="0.010211264227026 -0.0397887357729738 -1.38777878078145E-17"
        rpy="0 0 0" />
      <mass
        value="1.66549574268383" />
      <inertia
        ixx="0.00204748802629827"
        ixy="0.00031733979871691"
        ixz="-2.46875710098907E-20"
        iyy="0.00204748802629827"
        iyz="2.61953084223851E-20"
        izz="0.00201310637424175" />
    </inertial>
    <visual>
      <origin
        xyz="0 0 0"
        rpy="0 0 0" />
      <geometry>
        <mesh
          filename="package://terp2/meshes/link_arm_5.STL" />
      </geometry>
      <material
        name="">
        <color
          rgba="0.898039215686275 0.917647058823529 0.929411764705882 1" />
      </material>
    </visual>
    <collision>
      <origin
        xyz="0 0 0"
        rpy="0 0 0" />
      <geometry>
        <mesh
          filename="package://terp2/meshes/link_arm_5.STL" />
      </geometry>
    </collision>
  </link>
  <joint
    name="joint_arm_5"
    type="continuous">
    <origin
      xyz="0.15 0.05 0"
      rpy="1.5707963267949 -1.5707963267949 0" />
    <parent
      link="link_arm_4" />
    <child
      link="link_arm_5" />
    <axis
      xyz="0 1 0" />
  </joint>
  <link
    name="link_gripper_base">
    <inertial>
      <origin
        xyz="0 0.085172063756944 -1.38777878078145E-17"
        rpy="0 0 0" />
      <mass
        value="4.17469561621429" />
      <inertia
        ixx="0.0106568078407958"
        ixy="5.87734723477E-19"
        ixz="-2.02628723288863E-18"
        iyy="0.0113006453086544"
        iyz="5.85192781012409E-20"
        izz="0.0156869078407958" />
    </inertial>
    <visual>
      <origin
        xyz="0 0 0"
        rpy="0 0 0" />
      <geometry>
        <mesh
          filename="package://terp2/meshes/link_gripper_base.STL" />
      </geometry>
      <material
        name="">
        <color
          rgba="0.898039215686275 0.917647058823529 0.929411764705882 1" />
      </material>
    </visual>
    <collision>
      <origin
        xyz="0 0 0"
        rpy="0 0 0" />
      <geometry>
        <mesh
          filename="package://terp2/meshes/link_gripper_base.STL" />
      </geometry>
    </collision>
  </link>
  <joint
    name="joint_gripper_base"
    type="continuous">
    <origin
      xyz="0.0499999999999999 -0.05 0"
      rpy="3.14159265358979 0 1.5707963267949" />
    <parent
      link="link_arm_5" />
    <child
      link="link_gripper_base" />
    <axis
      xyz="0 1 0" />
  </joint>
  <link
    name="link_gripper_gear">
    <inertial>
      <origin
        xyz="0 0.005 -1.38777878078145E-17"
        rpy="0 0 0" />
      <mass
        value="0.307799999999999" />
      <inertia
        ixx="0.000822396019736841"
        ixy="9.9158388157895E-05"
        ixz="-4.99588815789485E-06"
        iyy="0.000259132944078947"
        iyz="-8.79476151315788E-05"
        izz="0.000816142944078946" />
    </inertial>
    <visual>
      <origin
        xyz="0 0 0"
        rpy="0 0 0" />
      <geometry>
        <mesh
          filename="package://terp2/meshes/link_gripper_gear.STL" />
      </geometry>
      <material
        name="">
        <color
          rgba="0.898039215686275 0.917647058823529 0.929411764705882 1" />
      </material>
    </visual>
    <collision>
      <origin
        xyz="0 0 0"
        rpy="0 0 0" />
      <geometry>
        <mesh
          filename="package://terp2/meshes/link_gripper_gear.STL" />
      </geometry>
    </collision>
  </link>
  <joint
    name="joint_gripper_gear"
    type="continuous">
    <origin
      xyz="0 0.15 0"
      rpy="3.14159265358979 0 3.14159265358979" />
    <parent
      link="link_gripper_base" />
    <child
      link="link_gripper_gear" />
    <axis
      xyz="0 1 0" />
  </joint>
  <link
    name="link_gripper_pad1">
    <inertial>
      <origin
        xyz="0.00723684210526308 -0.00730263157894756 -0.0651973684210527"
        rpy="0 0 0" />
      <mass
        value="0.307799999999999" />
      <inertia
        ixx="0.000822396019736841"
        ixy="9.9158388157895E-05"
        ixz="-4.99588815789485E-06"
        iyy="0.000259132944078947"
        iyz="-8.79476151315788E-05"
        izz="0.000816142944078946" />
    </inertial>
    <visual>
      <origin
        xyz="0 0 0"
        rpy="0 0 0" />
      <geometry>
        <mesh
          filename="package://terp2/meshes/link_gripper_pad1.STL" />
      </geometry>
      <material
        name="">
        <color
          rgba="0.898039215686275 0.917647058823529 0.929411764705882 1" />
      </material>
    </visual>
    <collision>
      <origin
        xyz="0 0 0"
        rpy="0 0 0" />
      <geometry>
        <mesh
          filename="package://terp2/meshes/link_gripper_pad1.STL" />
      </geometry>
    </collision>
  </link>
  <joint
    name="joint_gripper_pad1"
    type="prismatic">
    <origin
      xyz="0 0.2 0"
      rpy="0 1.5707963267949 0" />
    <parent
      link="link_gripper_base" />
    <child
      link="link_gripper_pad1" />
    <axis
      xyz="0 0 1" />
    <limit
      lower="0"
      upper="0.055"
      effort="0"
      velocity="0" />
  </joint>
  <link
    name="link_gripper_pad2">
    <inertial>
      <origin
        xyz="0.00723684210526321 0.0926973684210526 -0.0651973684210526"
        rpy="0 0 0" />
      <mass
        value="0.3078" />
      <inertia
        ixx="0.000822396019736842"
        ixy="9.91583881578946E-05"
        ixz="-4.99588815789471E-06"
        iyy="0.000259132944078947"
        iyz="-8.7947615131579E-05"
        izz="0.000816142944078947" />
    </inertial>
    <visual>
      <origin
        xyz="0 0 0"
        rpy="0 0 0" />
      <geometry>
        <mesh
          filename="package://terp2/meshes/link_gripper_pad2.STL" />
      </geometry>
      <material
        name="">
        <color
          rgba="0.898039215686275 0.917647058823529 0.929411764705882 1" />
      </material>
    </visual>
    <collision>
      <origin
        xyz="0 0 0"
        rpy="0 0 0" />
      <geometry>
        <mesh
          filename="package://terp2/meshes/link_gripper_pad2.STL" />
      </geometry>
    </collision>
  </link>
  <joint
    name="joint_gripper_pad2"
    type="prismatic">
    <origin
      xyz="0 0.1 0"
      rpy="0 -1.5708 15708" />
    <parent
      link="link_gripper_base" />
    <child
      link="link_gripper_pad2" />
    <axis
      xyz="0 0 1" />
    <limit
      lower="0"
      upper="0.055"
      effort="0"
      velocity="0" />
  </joint>
  <link
    name="link_axle">
    <inertial>
      <origin
        xyz="-9.89050624297408E-18 0.0187933133528535 -2.40081054334435E-16"
        rpy="0 0 0" />
      <mass
        value="4.39338382957022" />
      <inertia
        ixx="0.00285404464776084"
        ixy="-1.64730992102492E-19"
        ixz="7.11884371153108E-19"
        iyy="0.072618050374337"
        iyz="-5.12846005076799E-20"
        izz="0.0733554323820936" />
    </inertial>
    <visual>
      <origin
        xyz="0 0 0"
        rpy="0 0 0" />
      <geometry>
        <mesh
          filename="package://terp2/meshes/link_axle.STL" />
      </geometry>
      <material
        name="">
        <color
          rgba="0.898039215686275 0.917647058823529 0.929411764705882 1" />
      </material>
    </visual>
    <collision>
      <origin
        xyz="0 0 0"
        rpy="0 0 0" />
      <geometry>
        <mesh
          filename="package://terp2/meshes/link_axle.STL" />
      </geometry>
    </collision>
  </link>
  <joint
    name="joint_axle"
    type="fixed">
    <origin
      xyz="0 0 -0.66"
      rpy="1.5708 0 0" />
    <parent
      link="base_link" />
    <child
      link="link_axle" />
    <axis
      xyz="0 0 0" />
  </joint>
  <link
    name="link_drivewheel_right">
    <inertial>
      <origin
        xyz="-1.80507259650104E-16 -1.11022302462516E-16 -0.015"
        rpy="0 0 0" />
      <mass
        value="0.558241379588822" />
      <inertia
        ixx="0.000420507545615752"
        ixy="8.59854246748872E-20"
        ixz="-1.53545401205157E-22"
        iyy="0.000420507545615752"
        iyz="-1.39586728368322E-22"
        izz="0.000757278884293181" />
    </inertial>
    <visual>
      <origin
        xyz="0 0 0"
        rpy="0 0 0" />
      <geometry>
        <mesh
          filename="package://terp2/meshes/link_drivewheel_right.STL" />
      </geometry>
      <material
        name="">
        <color
          rgba="0.898039215686275 0.917647058823529 0.929411764705882 1" />
      </material>
    </visual>
    <collision>
      <origin
        xyz="0 0 0"
        rpy="0 0 0" />
      <geometry>
        <mesh
          filename="package://terp2/meshes/link_drivewheel_right.STL" />
      </geometry>
    </collision>
  </link>
  <joint
    name="joint_drivewheel_right"
    type="continuous">
    <origin
      xyz="-0.27 0 0"
      rpy="0 -1.5707963267949 0" />
    <parent
      link="link_axle" />
    <child
      link="link_drivewheel_right" />
    <axis
      xyz="0 0 1" />
  </joint>
  <link
    name="link_drivewheel_left">
    <inertial>
      <origin
        xyz="-1.80507259650104E-16 -1.11022302462516E-16 0.015"
        rpy="0 0 0" />
      <mass
        value="0.558241379588822" />
      <inertia
        ixx="0.000420507545615752"
        ixy="8.61498578409051E-20"
        ixz="-1.53545401205157E-22"
        iyy="0.000420507545615752"
        iyz="-1.39586728368322E-22"
        izz="0.000757278884293181" />
    </inertial>
    <visual>
      <origin
        xyz="0 0 0"
        rpy="0 0 0" />
      <geometry>
        <mesh
          filename="package://terp2/meshes/link_drivewheel_left.STL" />
      </geometry>
      <material
        name="">
        <color
          rgba="0.898039215686275 0.917647058823529 0.929411764705882 1" />
      </material>
    </visual>
    <collision>
      <origin
        xyz="0 0 0"
        rpy="0 0 0" />
      <geometry>
        <mesh
          filename="package://terp2/meshes/link_drivewheel_left.STL" />
      </geometry>
    </collision>
  </link>
  <joint
    name="joint_drivewheel_left"
    type="continuous">
    <origin
      xyz="0.27 0 0"
      rpy="0 -1.5707963267949 0" />
    <parent
      link="link_axle" />
    <child
      link="link_drivewheel_left" />
    <axis
      xyz="0 0 1" />
  </joint>
  <link
    name="link_swivel_front">
    <inertial>
      <origin
        xyz="0.00751421605065076 -0.0638265063331359 0"
        rpy="0 0 0" />
      <mass
        value="0.0627024001105494" />
      <inertia
        ixx="3.59765245107689E-05"
        ixy="-6.64637878744579E-06"
        ixz="-4.05272785176755E-22"
        iyy="1.44744242445051E-05"
        iyz="-6.32773395706454E-22"
        izz="4.70578674336986E-05" />
    </inertial>
    <visual>
      <origin
        xyz="0 0 0"
        rpy="0 0 0" />
      <geometry>
        <mesh
          filename="package://terp2/meshes/link_swivel_front.STL" />
      </geometry>
      <material
        name="">
        <color
          rgba="0.898039215686275 0.917647058823529 0.929411764705882 1" />
      </material>
    </visual>
    <collision>
      <origin
        xyz="0 0 0"
        rpy="0 0 0" />
      <geometry>
        <mesh
          filename="package://terp2/meshes/link_swivel_front.STL" />
      </geometry>
    </collision>
  </link>
  <joint
    name="joint_swivel_front"
    type="continuous">
    <origin
      xyz="0 -0.25983 -0.595"
      rpy="1.5708 0 0" />
    <parent
      link="base_link" />
    <child
      link="link_swivel_front" />
    <axis
      xyz="0 1 0" />
  </joint>
  <link
    name="link_swivelwheel_front">
    <inertial>
      <origin
        xyz="0 0 2.62324917533259E-18"
        rpy="0 0 0" />
      <mass
        value="0.281569121165131" />
      <inertia
        ixx="0.000133618705200673"
        ixy="2.29620168165892E-20"
        ixz="5.42345990842091E-21"
        iyy="0.000133618705200673"
        iyz="-1.12237552734842E-20"
        izz="0.000225002042226577" />
    </inertial>
    <visual>
      <origin
        xyz="0 0 0"
        rpy="0 0 0" />
      <geometry>
        <mesh
          filename="package://terp2/meshes/link_swivelwheel_front.STL" />
      </geometry>
      <material
        name="">
        <color
          rgba="0.898039215686275 0.917647058823529 0.929411764705882 1" />
      </material>
    </visual>
    <collision>
      <origin
        xyz="0 0 0"
        rpy="0 0 0" />
      <geometry>
        <mesh
          filename="package://terp2/meshes/link_swivelwheel_front.STL" />
      </geometry>
    </collision>
  </link>
  <joint
    name="joint_swivelwheel_front"
    type="continuous">
    <origin
      xyz="0 -0.0775 0"
      rpy="0 -1.5707963267949 0" />
    <parent
      link="link_swivel_front" />
    <child
      link="link_swivelwheel_front" />
    <axis
      xyz="0 0 1" />
  </joint>
  <link
    name="link_swivel_back">
    <inertial>
      <origin
        xyz="0.00751421605065053 -0.0638265063331358 0"
        rpy="0 0 0" />
      <mass
        value="0.0627024001105494" />
      <inertia
        ixx="3.59765245107689E-05"
        ixy="-6.6463787874458E-06"
        ixz="-4.21368739414295E-22"
        iyy="1.44744242445051E-05"
        iyz="-5.85471765025053E-22"
        izz="4.70578674336986E-05" />
    </inertial>
    <visual>
      <origin
        xyz="0 0 0"
        rpy="0 0 0" />
      <geometry>
        <mesh
          filename="package://terp2/meshes/link_swivel_back.STL" />
      </geometry>
      <material
        name="">
        <color
          rgba="0.898039215686275 0.917647058823529 0.929411764705882 1" />
      </material>
    </visual>
    <collision>
      <origin
        xyz="0 0 0"
        rpy="0 0 0" />
      <geometry>
        <mesh
          filename="package://terp2/meshes/link_swivel_back.STL" />
      </geometry>
    </collision>
  </link>
  <joint
    name="joint_swivel_back"
    type="continuous">
    <origin
      xyz="0 0.25982621214848 -0.595"
      rpy="1.5707963267949 0 3.14159265358979" />
    <parent
      link="base_link" />
    <child
      link="link_swivel_back" />
    <axis
      xyz="0 1 0" />
  </joint>
  <link
    name="link_swivelwheel_back">
    <inertial>
      <origin
        xyz="1.11022302462516E-16 0 2.23022790081543E-16"
        rpy="0 0 0" />
      <mass
        value="0.281569121165131" />
      <inertia
        ixx="0.000133618705200673"
        ixy="-2.29271201344972E-20"
        ixz="5.76740160712044E-21"
        iyy="0.000133618705200673"
        iyz="-3.28937579428345E-23"
        izz="0.000225002042226577" />
    </inertial>
    <visual>
      <origin
        xyz="0 0 0"
        rpy="0 0 0" />
      <geometry>
        <mesh
          filename="package://terp2/meshes/link_swivelwheel_back.STL" />
      </geometry>
      <material
        name="">
        <color
          rgba="0.898039215686275 0.917647058823529 0.929411764705882 1" />
      </material>
    </visual>
    <collision>
      <origin
        xyz="0 0 0"
        rpy="0 0 0" />
      <geometry>
        <mesh
          filename="package://terp2/meshes/link_swivelwheel_back.STL" />
      </geometry>
    </collision>
  </link>
  <joint
    name="joint_swivelwheel_back"
    type="continuous">
    <origin
      xyz="0 -0.0775 0"
      rpy="3.14159265358979 -1.5707963267949 0" />
    <parent
      link="link_swivel_back" />
    <child
      link="link_swivelwheel_back" />
    <axis
      xyz="0 0 1" />
  </joint>
</robot>
