<sdf version='1.7'>
  <world name='default'>
    <model name='ground_plane'>
      <static>1</static>
      <link name='link'>
        <collision name='collision'>
          <geometry>
            <plane>
              <normal>0 0 1</normal>
              <size>100 100</size>
            </plane>
          </geometry>
          <surface>
            <friction>
              <ode>
                <mu>100</mu>
                <mu2>50</mu2>
              </ode>
              <torsional>
                <ode/>
              </torsional>
            </friction>
            <contact>
              <ode/>
            </contact>
            <bounce/>
          </surface>
          <max_contacts>10</max_contacts>
        </collision>
        <visual name='visual'>
          <cast_shadows>0</cast_shadows>
          <geometry>
            <plane>
              <normal>0 0 1</normal>
              <size>100 100</size>
            </plane>
          </geometry>
          <material>
            <script>
              <uri>file://media/materials/scripts/gazebo.material</uri>
              <name>Gazebo/Grey</name>
            </script>
          </material>
        </visual>
        <self_collide>0</self_collide>
        <enable_wind>0</enable_wind>
        <kinematic>0</kinematic>
      </link>
    </model>
    <light name='sun' type='directional'>
      <cast_shadows>1</cast_shadows>
      <pose>0 0 10 0 -0 0</pose>
      <diffuse>0.8 0.8 0.8 1</diffuse>
      <specular>0.2 0.2 0.2 1</specular>
      <attenuation>
        <range>1000</range>
        <constant>0.9</constant>
        <linear>0.01</linear>
        <quadratic>0.001</quadratic>
      </attenuation>
      <direction>-0.5 0.1 -0.9</direction>
      <spot>
        <inner_angle>0</inner_angle>
        <outer_angle>0</outer_angle>
        <falloff>0</falloff>
      </spot>
    </light>
    <scene>
      <shadows>0</shadows>
      <ambient>0.4 0.4 0.4 1</ambient>
      <background>0.7 0.7 0.7 1</background>
    </scene>
    <gui fullscreen='0'>
      <camera name='user_camera'>
        <pose>-1.0592 -5.75416 6.63359 0 0.6378 1.44078</pose>
        <view_controller>orbit</view_controller>
        <projection_type>perspective</projection_type>
      </camera>
    </gui>
    <physics type='ode'>
      <real_time_update_rate>1000</real_time_update_rate>
      <max_step_size>0.001</max_step_size>
      <real_time_factor>1</real_time_factor>
      <ode>
        <solver>
          <type>quick</type>
          <iters>150</iters>
          <precon_iters>0</precon_iters>
          <sor>1.4</sor>
          <use_dynamic_moi_rescaling>1</use_dynamic_moi_rescaling>
        </solver>
        <constraints>
          <cfm>1e-05</cfm>
          <erp>0.2</erp>
          <contact_max_correcting_vel>2000</contact_max_correcting_vel>
          <contact_surface_layer>0.01</contact_surface_layer>
        </constraints>
      </ode>
    </physics>
    <plugin name='gazebo_ros_state' filename='libgazebo_ros_state.so'>
      <ros>
        <namespace>/gazebo</namespace>
      </ros>
      <update_rate>1.0</update_rate>
    </plugin>
    <gravity>0 0 -9.8</gravity>
    <magnetic_field>6e-06 2.3e-05 -4.2e-05</magnetic_field>
    <atmosphere type='adiabatic'/>
    <audio>
      <device>default</device>
    </audio>
    <wind/>
    <spherical_coordinates>
      <surface_model>EARTH_WGS84</surface_model>
      <latitude_deg>0</latitude_deg>
      <longitude_deg>0</longitude_deg>
      <elevation>0</elevation>
      <heading_deg>0</heading_deg>
    </spherical_coordinates>
    <model name='terp2'>
      <link name='base_link'>
        <inertial>
          <pose>-0 -0 -0.435968 0 -0 0</pose>
          <mass>55</mass>
          <inertia>
            <ixx>55.2317</ixx>
            <ixy>-2.4497e-24</ixy>
            <ixz>-8.01156e-18</ixz>
            <iyy>55.2317</iyy>
            <iyz>-7.084e-08</iyz>
            <izz>105</izz>
          </inertia>
        </inertial>
        <collision name='base_link_collision'>
          <pose>0 0 0 0 -0 0</pose>
          <geometry>
            <mesh>
              <scale>1 1 1</scale>
              <uri>model://terp2/meshes/base_link.STL</uri>
            </mesh>
          </geometry>
          <max_contacts>10</max_contacts>
          <surface>
            <contact>
              <ode/>
            </contact>
            <bounce/>
            <friction>
              <torsional>
                <ode/>
              </torsional>
              <ode/>
            </friction>
          </surface>
        </collision>
        <collision name='base_link_fixed_joint_lump__link_axle_collision_1'>
          <pose>0 0 -0.66 1.5708 -0 0</pose>
          <geometry>
            <mesh>
              <scale>1 1 1</scale>
              <uri>model://terp2/meshes/link_axle.STL</uri>
            </mesh>
          </geometry>
          <max_contacts>10</max_contacts>
          <surface>
            <contact>
              <ode/>
            </contact>
            <bounce/>
            <friction>
              <torsional>
                <ode/>
              </torsional>
              <ode/>
            </friction>
          </surface>
        </collision>
        <visual name='base_link_visual'>
          <pose>0 0 0 0 -0 0</pose>
          <geometry>
            <mesh>
              <scale>1 1 1</scale>
              <uri>model://terp2/meshes/base_link.STL</uri>
            </mesh>
          </geometry>
        </visual>
        <visual name='base_link_fixed_joint_lump__link_axle_visual_1'>
          <pose>0 0 -0.66 1.5708 -0 0</pose>
          <geometry>
            <mesh>
              <scale>1 1 1</scale>
              <uri>model://terp2/meshes/link_axle.STL</uri>
            </mesh>
          </geometry>
        </visual>
        <self_collide>0</self_collide>
        <enable_wind>0</enable_wind>
        <kinematic>0</kinematic>
      </link>
      <joint name='joint_arm_1' type='revolute'>
        <pose relative_to='base_link'>0 0.01 0 1.5708 -0 0</pose>
        <parent>base_link</parent>
        <child>link_arm_1</child>
        <axis>
          <xyz>0 1 0</xyz>
          <limit>
            <lower>-1e+16</lower>
            <upper>1e+16</upper>
          </limit>
          <dynamics>
            <spring_reference>0</spring_reference>
            <spring_stiffness>0</spring_stiffness>
          </dynamics>
        </axis>
      </joint>
      <link name='link_arm_1'>
        <pose relative_to='joint_arm_1'>0 0 0 0 -0 0</pose>
        <inertial>
          <pose>0.010211 0.049789 0.01 0 -0 0</pose>
          <mass>1</mass>
          <inertia>
            <ixx>1</ixx>
            <ixy>0</ixy>
            <ixz>0</ixz>
            <iyy>1</iyy>
            <iyz>0</iyz>
            <izz>1</izz>
          </inertia>
        </inertial>
        <collision name='link_arm_1_collision'>
          <pose>0 0 0 0 -0 0</pose>
          <geometry>
            <mesh>
              <scale>1 1 1</scale>
              <uri>model://terp2/meshes/link_arm_1.STL</uri>
            </mesh>
          </geometry>
          <max_contacts>10</max_contacts>
          <surface>
            <contact>
              <ode/>
            </contact>
            <bounce/>
            <friction>
              <torsional>
                <ode/>
              </torsional>
              <ode/>
            </friction>
          </surface>
        </collision>
        <visual name='link_arm_1_visual'>
          <pose>0 0 0 0 -0 0</pose>
          <geometry>
            <mesh>
              <scale>1 1 1</scale>
              <uri>model://terp2/meshes/link_arm_1.STL</uri>
            </mesh>
          </geometry>
        </visual>
        <self_collide>0</self_collide>
        <enable_wind>0</enable_wind>
        <kinematic>0</kinematic>
      </link>
      <joint name='joint_arm_2' type='revolute'>
        <pose relative_to='link_arm_1'>0.04995 0.06 0.01 3.14159 -0 1.5708</pose>
        <parent>link_arm_1</parent>
        <child>link_arm_2</child>
        <axis>
          <xyz>0 1 0</xyz>
          <limit>
            <lower>-1e+16</lower>
            <upper>1e+16</upper>
          </limit>
          <dynamics>
            <spring_reference>0</spring_reference>
            <spring_stiffness>0</spring_stiffness>
          </dynamics>
        </axis>
      </joint>
      <link name='link_arm_2'>
        <pose relative_to='joint_arm_2'>0 0 0 0 -0 0</pose>
        <inertial>
          <pose>0.425 0.047952 0 0 -0 0</pose>
          <mass>1</mass>
          <inertia>
            <ixx>1</ixx>
            <ixy>0</ixy>
            <ixz>0</ixz>
            <iyy>1</iyy>
            <iyz>0</iyz>
            <izz>1</izz>
          </inertia>
        </inertial>
        <collision name='link_arm_2_collision'>
          <pose>0 0 0 0 -0 0</pose>
          <geometry>
            <mesh>
              <scale>1 1 1</scale>
              <uri>model://terp2/meshes/link_arm_2.STL</uri>
            </mesh>
          </geometry>
          <max_contacts>10</max_contacts>
          <surface>
            <contact>
              <ode/>
            </contact>
            <bounce/>
            <friction>
              <torsional>
                <ode/>
              </torsional>
              <ode/>
            </friction>
          </surface>
        </collision>
        <visual name='link_arm_2_visual'>
          <pose>0 0 0 0 -0 0</pose>
          <geometry>
            <mesh>
              <scale>1 1 1</scale>
              <uri>model://terp2/meshes/link_arm_2.STL</uri>
            </mesh>
          </geometry>
        </visual>
        <self_collide>0</self_collide>
        <enable_wind>0</enable_wind>
        <kinematic>0</kinematic>
      </link>
      <joint name='joint_arm_3' type='revolute'>
        <pose relative_to='link_arm_2'>0.85 0 0 0 -0 3.14159</pose>
        <parent>link_arm_2</parent>
        <child>link_arm_3</child>
        <axis>
          <xyz>0 1 0</xyz>
          <limit>
            <lower>-1e+16</lower>
            <upper>1e+16</upper>
          </limit>
          <dynamics>
            <spring_reference>0</spring_reference>
            <spring_stiffness>0</spring_stiffness>
          </dynamics>
        </axis>
      </joint>
      <link name='link_arm_3'>
        <pose relative_to='joint_arm_3'>0 0 0 0 -0 0</pose>
        <inertial>
          <pose>0.375001 0.04995 0 0 -0 0</pose>
          <mass>1</mass>
          <inertia>
            <ixx>1</ixx>
            <ixy>0</ixy>
            <ixz>0</ixz>
            <iyy>1</iyy>
            <iyz>0</iyz>
            <izz>1</izz>
          </inertia>
        </inertial>
        <collision name='link_arm_3_collision'>
          <pose>0 0 0 0 -0 0</pose>
          <geometry>
            <mesh>
              <scale>1 1 1</scale>
              <uri>model://terp2/meshes/link_arm_3.STL</uri>
            </mesh>
          </geometry>
          <max_contacts>10</max_contacts>
          <surface>
            <contact>
              <ode/>
            </contact>
            <bounce/>
            <friction>
              <torsional>
                <ode/>
              </torsional>
              <ode/>
            </friction>
          </surface>
        </collision>
        <visual name='link_arm_3_visual'>
          <pose>0 0 0 0 -0 0</pose>
          <geometry>
            <mesh>
              <scale>1 1 1</scale>
              <uri>model://terp2/meshes/link_arm_3.STL</uri>
            </mesh>
          </geometry>
        </visual>
        <self_collide>0</self_collide>
        <enable_wind>0</enable_wind>
        <kinematic>0</kinematic>
      </link>
      <joint name='joint_arm_4' type='revolute'>
        <pose relative_to='link_arm_3'>0.75 0.09995 0 3.14159 -0 3.14159</pose>
        <parent>link_arm_3</parent>
        <child>link_arm_4</child>
        <axis>
          <xyz>0 1 0</xyz>
          <limit>
            <lower>-1e+16</lower>
            <upper>1e+16</upper>
          </limit>
          <dynamics>
            <spring_reference>0</spring_reference>
            <spring_stiffness>0</spring_stiffness>
          </dynamics>
        </axis>
      </joint>
      <link name='link_arm_4'>
        <pose relative_to='joint_arm_4'>0 0 0 0 -0 0</pose>
        <inertial>
          <pose>0.055798 0.044973 -0 0 -0 0</pose>
          <mass>1</mass>
          <inertia>
            <ixx>1</ixx>
            <ixy>0</ixy>
            <ixz>0</ixz>
            <iyy>1</iyy>
            <iyz>0</iyz>
            <izz>1</izz>
          </inertia>
        </inertial>
        <collision name='link_arm_4_collision'>
          <pose>0 0 0 0 -0 0</pose>
          <geometry>
            <mesh>
              <scale>1 1 1</scale>
              <uri>model://terp2/meshes/link_arm_4.STL</uri>
            </mesh>
          </geometry>
          <max_contacts>10</max_contacts>
          <surface>
            <contact>
              <ode/>
            </contact>
            <bounce/>
            <friction>
              <torsional>
                <ode/>
              </torsional>
              <ode/>
            </friction>
          </surface>
        </collision>
        <visual name='link_arm_4_visual'>
          <pose>0 0 0 0 -0 0</pose>
          <geometry>
            <mesh>
              <scale>1 1 1</scale>
              <uri>model://terp2/meshes/link_arm_4.STL</uri>
            </mesh>
          </geometry>
        </visual>
        <self_collide>0</self_collide>
        <enable_wind>0</enable_wind>
        <kinematic>0</kinematic>
      </link>
      <joint name='joint_arm_5' type='revolute'>
        <pose relative_to='link_arm_4'>0.15 0.05 0 -1.57079 -1.57079 3.14159</pose>
        <parent>link_arm_4</parent>
        <child>link_arm_5</child>
        <axis>
          <xyz>0 1 0</xyz>
          <limit>
            <lower>-1e+16</lower>
            <upper>1e+16</upper>
          </limit>
          <dynamics>
            <spring_reference>0</spring_reference>
            <spring_stiffness>0</spring_stiffness>
          </dynamics>
        </axis>
      </joint>
      <link name='link_arm_5'>
        <pose relative_to='joint_arm_5'>0 0 0 0 -0 0</pose>
        <inertial>
          <pose>0.010211 -0.039789 -0 0 -0 0</pose>
          <mass>1</mass>
          <inertia>
            <ixx>1</ixx>
            <ixy>0</ixy>
            <ixz>0</ixz>
            <iyy>1</iyy>
            <iyz>0</iyz>
            <izz>1</izz>
          </inertia>
        </inertial>
        <collision name='link_arm_5_collision'>
          <pose>0 0 0 0 -0 0</pose>
          <geometry>
            <mesh>
              <scale>1 1 1</scale>
              <uri>model://terp2/meshes/link_arm_5.STL</uri>
            </mesh>
          </geometry>
          <max_contacts>10</max_contacts>
          <surface>
            <contact>
              <ode/>
            </contact>
            <bounce/>
            <friction>
              <torsional>
                <ode/>
              </torsional>
              <ode/>
            </friction>
          </surface>
        </collision>
        <visual name='link_arm_5_visual'>
          <pose>0 0 0 0 -0 0</pose>
          <geometry>
            <mesh>
              <scale>1 1 1</scale>
              <uri>model://terp2/meshes/link_arm_5.STL</uri>
            </mesh>
          </geometry>
        </visual>
        <self_collide>0</self_collide>
        <enable_wind>0</enable_wind>
        <kinematic>0</kinematic>
      </link>
      <joint name='joint_gripper_base' type='revolute'>
        <pose relative_to='link_arm_5'>0.05 -0.05 0 3.14159 -0 1.5708</pose>
        <parent>link_arm_5</parent>
        <child>link_gripper_base</child>
        <axis>
          <xyz>0 1 0</xyz>
          <limit>
            <lower>-1e+16</lower>
            <upper>1e+16</upper>
          </limit>
          <dynamics>
            <spring_reference>0</spring_reference>
            <spring_stiffness>0</spring_stiffness>
          </dynamics>
        </axis>
      </joint>
      <link name='link_gripper_base'>
        <pose relative_to='joint_gripper_base'>0 0 0 0 -0 0</pose>
        <inertial>
          <pose>0 0.085172 -0 0 -0 0</pose>
          <mass>1</mass>
          <inertia>
            <ixx>1</ixx>
            <ixy>0</ixy>
            <ixz>0</ixz>
            <iyy>1</iyy>
            <iyz>0</iyz>
            <izz>1</izz>
          </inertia>
        </inertial>
        <collision name='link_gripper_base_collision'>
          <pose>0 0 0 0 -0 0</pose>
          <geometry>
            <mesh>
              <scale>1 1 1</scale>
              <uri>model://terp2/meshes/link_gripper_base.STL</uri>
            </mesh>
          </geometry>
          <max_contacts>10</max_contacts>
          <surface>
            <contact>
              <ode/>
            </contact>
            <bounce/>
            <friction>
              <torsional>
                <ode/>
              </torsional>
              <ode/>
            </friction>
          </surface>
        </collision>
        <visual name='link_gripper_base_visual'>
          <pose>0 0 0 0 -0 0</pose>
          <geometry>
            <mesh>
              <scale>1 1 1</scale>
              <uri>model://terp2/meshes/link_gripper_base.STL</uri>
            </mesh>
          </geometry>
        </visual>
        <self_collide>0</self_collide>
        <enable_wind>0</enable_wind>
        <kinematic>0</kinematic>
      </link>
      <joint name='joint_gripper_gear' type='revolute'>
        <pose relative_to='link_gripper_base'>0 0.15 0 3.14159 -0 3.14159</pose>
        <parent>link_gripper_base</parent>
        <child>link_gripper_gear</child>
        <axis>
          <xyz>0 1 0</xyz>
          <limit>
            <lower>-1e+16</lower>
            <upper>1e+16</upper>
          </limit>
          <dynamics>
            <spring_reference>0</spring_reference>
            <spring_stiffness>0</spring_stiffness>
          </dynamics>
        </axis>
      </joint>
      <link name='link_gripper_gear'>
        <pose relative_to='joint_gripper_gear'>0 0 0 0 -0 0</pose>
        <inertial>
          <pose>0 0.005 -0 0 -0 0</pose>
          <mass>1</mass>
          <inertia>
            <ixx>1</ixx>
            <ixy>0</ixy>
            <ixz>0</ixz>
            <iyy>1</iyy>
            <iyz>0</iyz>
            <izz>1</izz>
          </inertia>
        </inertial>
        <collision name='link_gripper_gear_collision'>
          <pose>0 0 0 0 -0 0</pose>
          <geometry>
            <mesh>
              <scale>1 1 1</scale>
              <uri>model://terp2/meshes/link_gripper_gear.STL</uri>
            </mesh>
          </geometry>
          <max_contacts>10</max_contacts>
          <surface>
            <contact>
              <ode/>
            </contact>
            <bounce/>
            <friction>
              <torsional>
                <ode/>
              </torsional>
              <ode/>
            </friction>
          </surface>
        </collision>
        <visual name='link_gripper_gear_visual'>
          <pose>0 0 0 0 -0 0</pose>
          <geometry>
            <mesh>
              <scale>1 1 1</scale>
              <uri>model://terp2/meshes/link_gripper_gear.STL</uri>
            </mesh>
          </geometry>
        </visual>
        <self_collide>0</self_collide>
        <enable_wind>0</enable_wind>
        <kinematic>0</kinematic>
      </link>
      <joint name='joint_gripper_pad1' type='prismatic'>
        <pose relative_to='link_gripper_base'>0 0.2 0 3.14159 1.57079 3.14159</pose>
        <parent>link_gripper_base</parent>
        <child>link_gripper_pad1</child>
        <axis>
          <xyz>0 0 1</xyz>
          <limit>
            <lower>0</lower>
            <upper>0.055</upper>
            <effort>0</effort>
            <velocity>0</velocity>
          </limit>
          <dynamics>
            <spring_reference>0</spring_reference>
            <spring_stiffness>0</spring_stiffness>
          </dynamics>
        </axis>
      </joint>
      <link name='link_gripper_pad1'>
        <pose relative_to='joint_gripper_pad1'>0 0 0 0 -0 0</pose>
        <inertial>
          <pose>0.007237 -0.007303 -0.065197 0 -0 0</pose>
          <mass>1</mass>
          <inertia>
            <ixx>1</ixx>
            <ixy>0</ixy>
            <ixz>0</ixz>
            <iyy>1</iyy>
            <iyz>0</iyz>
            <izz>1</izz>
          </inertia>
        </inertial>
        <collision name='link_gripper_pad1_collision'>
          <pose>0 0 0 0 -0 0</pose>
          <geometry>
            <mesh>
              <scale>1 1 1</scale>
              <uri>model://terp2/meshes/link_gripper_pad1.STL</uri>
            </mesh>
          </geometry>
          <max_contacts>10</max_contacts>
          <surface>
            <contact>
              <ode/>
            </contact>
            <bounce/>
            <friction>
              <torsional>
                <ode/>
              </torsional>
              <ode/>
            </friction>
          </surface>
        </collision>
        <visual name='link_gripper_pad1_visual'>
          <pose>0 0 0 0 -0 0</pose>
          <geometry>
            <mesh>
              <scale>1 1 1</scale>
              <uri>model://terp2/meshes/link_gripper_pad1.STL</uri>
            </mesh>
          </geometry>
        </visual>
        <self_collide>0</self_collide>
        <enable_wind>0</enable_wind>
        <kinematic>0</kinematic>
      </link>
      <joint name='joint_gripper_pad2' type='prismatic'>
        <pose relative_to='link_gripper_base'>0 0.1 0 3.14159 -1.57079 -3.10486</pose>
        <parent>link_gripper_base</parent>
        <child>link_gripper_pad2</child>
        <axis>
          <xyz>0 0 1</xyz>
          <limit>
            <lower>0</lower>
            <upper>0.055</upper>
            <effort>0</effort>
            <velocity>0</velocity>
          </limit>
          <dynamics>
            <spring_reference>0</spring_reference>
            <spring_stiffness>0</spring_stiffness>
          </dynamics>
        </axis>
      </joint>
      <link name='link_gripper_pad2'>
        <pose relative_to='joint_gripper_pad2'>0 0 0 0 -0 0</pose>
        <inertial>
          <pose>0.007237 0.092697 -0.065197 0 -0 0</pose>
          <mass>1</mass>
          <inertia>
            <ixx>1</ixx>
            <ixy>0</ixy>
            <ixz>0</ixz>
            <iyy>1</iyy>
            <iyz>0</iyz>
            <izz>1</izz>
          </inertia>
        </inertial>
        <collision name='link_gripper_pad2_collision'>
          <pose>0 0 0 0 -0 0</pose>
          <geometry>
            <mesh>
              <scale>1 1 1</scale>
              <uri>model://terp2/meshes/link_gripper_pad2.STL</uri>
            </mesh>
          </geometry>
          <max_contacts>10</max_contacts>
          <surface>
            <contact>
              <ode/>
            </contact>
            <bounce/>
            <friction>
              <torsional>
                <ode/>
              </torsional>
              <ode/>
            </friction>
          </surface>
        </collision>
        <visual name='link_gripper_pad2_visual'>
          <pose>0 0 0 0 -0 0</pose>
          <geometry>
            <mesh>
              <scale>1 1 1</scale>
              <uri>model://terp2/meshes/link_gripper_pad2.STL</uri>
            </mesh>
          </geometry>
        </visual>
        <self_collide>0</self_collide>
        <enable_wind>0</enable_wind>
        <kinematic>0</kinematic>
      </link>
      <joint name='joint_drivewheel_left' type='revolute'>
        <pose relative_to='base_link'>0.27 0 -0.66 1.5708 4e-06 -1.5708</pose>
        <parent>base_link</parent>
        <child>link_drivewheel_left</child>
        <axis>
          <xyz>0 0 1</xyz>
          <limit>
            <lower>-1e+16</lower>
            <upper>1e+16</upper>
          </limit>
          <dynamics>
            <spring_reference>0</spring_reference>
            <spring_stiffness>0</spring_stiffness>
          </dynamics>
        </axis>
      </joint>
      <link name='link_drivewheel_left'>
        <pose relative_to='joint_drivewheel_left'>0 0 0 0 -0 0</pose>
        <inertial>
          <pose>-0 -0 0.015 0 -0 0</pose>
          <mass>20</mass>
          <inertia>
            <ixx>20</ixx>
            <ixy>0</ixy>
            <ixz>0</ixz>
            <iyy>20</iyy>
            <iyz>0</iyz>
            <izz>20</izz>
          </inertia>
        </inertial>
        <collision name='link_drivewheel_left_collision'>
          <pose>0 0 0 0 -0 0</pose>
          <geometry>
            <mesh>
              <scale>1 1 1</scale>
              <uri>model://terp2/meshes/link_drivewheel_left.STL</uri>
            </mesh>
          </geometry>
          <max_contacts>10</max_contacts>
          <surface>
            <contact>
              <ode/>
            </contact>
            <bounce/>
            <friction>
              <torsional>
                <ode/>
              </torsional>
              <ode/>
            </friction>
          </surface>
        </collision>
        <visual name='link_drivewheel_left_visual'>
          <pose>0 0 0 0 -0 0</pose>
          <geometry>
            <mesh>
              <scale>1 1 1</scale>
              <uri>model://terp2/meshes/link_drivewheel_left.STL</uri>
            </mesh>
          </geometry>
        </visual>
        <self_collide>0</self_collide>
        <enable_wind>0</enable_wind>
        <kinematic>0</kinematic>
      </link>
      <joint name='joint_drivewheel_right' type='revolute'>
        <pose relative_to='base_link'>-0.27 0 -0.66 1.5708 4e-06 -1.5708</pose>
        <parent>base_link</parent>
        <child>link_drivewheel_right</child>
        <axis>
          <xyz>0 0 1</xyz>
          <limit>
            <lower>-1e+16</lower>
            <upper>1e+16</upper>
          </limit>
          <dynamics>
            <spring_reference>0</spring_reference>
            <spring_stiffness>0</spring_stiffness>
          </dynamics>
        </axis>
      </joint>
      <link name='link_drivewheel_right'>
        <pose relative_to='joint_drivewheel_right'>0 0 0 0 -0 0</pose>
        <inertial>
          <pose>-0 -0 -0.015 0 -0 0</pose>
          <mass>20</mass>
          <inertia>
            <ixx>20</ixx>
            <ixy>0</ixy>
            <ixz>0</ixz>
            <iyy>20</iyy>
            <iyz>0</iyz>
            <izz>20</izz>
          </inertia>
        </inertial>
        <collision name='link_drivewheel_right_collision'>
          <pose>0 0 0 0 -0 0</pose>
          <geometry>
            <mesh>
              <scale>1 1 1</scale>
              <uri>model://terp2/meshes/link_drivewheel_right.STL</uri>
            </mesh>
          </geometry>
          <max_contacts>10</max_contacts>
          <surface>
            <contact>
              <ode/>
            </contact>
            <bounce/>
            <friction>
              <torsional>
                <ode/>
              </torsional>
              <ode/>
            </friction>
          </surface>
        </collision>
        <visual name='link_drivewheel_right_visual'>
          <pose>0 0 0 0 -0 0</pose>
          <geometry>
            <mesh>
              <scale>1 1 1</scale>
              <uri>model://terp2/meshes/link_drivewheel_right.STL</uri>
            </mesh>
          </geometry>
        </visual>
        <self_collide>0</self_collide>
        <enable_wind>0</enable_wind>
        <kinematic>0</kinematic>
      </link>
      <joint name='joint_swivel_back' type='revolute'>
        <pose relative_to='base_link'>0 0.259826 -0.595 1.5708 -0 3.14159</pose>
        <parent>base_link</parent>
        <child>link_swivel_back</child>
        <axis>
          <xyz>0 1 0</xyz>
          <limit>
            <lower>-1e+16</lower>
            <upper>1e+16</upper>
          </limit>
          <dynamics>
            <spring_reference>0</spring_reference>
            <spring_stiffness>0</spring_stiffness>
          </dynamics>
        </axis>
      </joint>
      <link name='link_swivel_back'>
        <pose relative_to='joint_swivel_back'>0 0 0 0 -0 0</pose>
        <inertial>
          <pose>0.007514 -0.063827 0 0 -0 0</pose>
          <mass>1</mass>
          <inertia>
            <ixx>1</ixx>
            <ixy>0</ixy>
            <ixz>0</ixz>
            <iyy>1</iyy>
            <iyz>0</iyz>
            <izz>1</izz>
          </inertia>
        </inertial>
        <collision name='link_swivel_back_collision'>
          <pose>0 0 0 0 -0 0</pose>
          <geometry>
            <mesh>
              <scale>1 1 1</scale>
              <uri>model://terp2/meshes/link_swivel_back.STL</uri>
            </mesh>
          </geometry>
          <max_contacts>10</max_contacts>
          <surface>
            <contact>
              <ode/>
            </contact>
            <bounce/>
            <friction>
              <torsional>
                <ode/>
              </torsional>
              <ode/>
            </friction>
          </surface>
        </collision>
        <visual name='link_swivel_back_visual'>
          <pose>0 0 0 0 -0 0</pose>
          <geometry>
            <mesh>
              <scale>1 1 1</scale>
              <uri>model://terp2/meshes/link_swivel_back.STL</uri>
            </mesh>
          </geometry>
        </visual>
        <self_collide>0</self_collide>
        <enable_wind>0</enable_wind>
        <kinematic>0</kinematic>
      </link>
      <joint name='joint_swivelwheel_back' type='revolute'>
        <pose relative_to='link_swivel_back'>0 -0.0775 0 -3e-06 -1.57079 3.14159</pose>
        <parent>link_swivel_back</parent>
        <child>link_swivelwheel_back</child>
        <axis>
          <xyz>0 0 1</xyz>
          <limit>
            <lower>-1e+16</lower>
            <upper>1e+16</upper>
          </limit>
          <dynamics>
            <spring_reference>0</spring_reference>
            <spring_stiffness>0</spring_stiffness>
          </dynamics>
        </axis>
      </joint>
      <link name='link_swivelwheel_back'>
        <pose relative_to='joint_swivelwheel_back'>0 0 0 0 -0 0</pose>
        <inertial>
          <pose>0 0 0 0 -0 0</pose>
          <mass>20</mass>
          <inertia>
            <ixx>20</ixx>
            <ixy>0</ixy>
            <ixz>0</ixz>
            <iyy>20</iyy>
            <iyz>0</iyz>
            <izz>20</izz>
          </inertia>
        </inertial>
        <collision name='link_swivelwheel_back_collision'>
          <pose>0 0 0 0 -0 0</pose>
          <geometry>
            <mesh>
              <scale>1 1 1</scale>
              <uri>model://terp2/meshes/link_swivelwheel_back.STL</uri>
            </mesh>
          </geometry>
          <max_contacts>10</max_contacts>
          <surface>
            <contact>
              <ode/>
            </contact>
            <bounce/>
            <friction>
              <torsional>
                <ode/>
              </torsional>
              <ode/>
            </friction>
          </surface>
        </collision>
        <visual name='link_swivelwheel_back_visual'>
          <pose>0 0 0 0 -0 0</pose>
          <geometry>
            <mesh>
              <scale>1 1 1</scale>
              <uri>model://terp2/meshes/link_swivelwheel_back.STL</uri>
            </mesh>
          </geometry>
        </visual>
        <self_collide>0</self_collide>
        <enable_wind>0</enable_wind>
        <kinematic>0</kinematic>
      </link>
      <joint name='joint_swivel_front' type='revolute'>
        <pose relative_to='base_link'>0 -0.25983 -0.595 1.5708 -0 0</pose>
        <parent>base_link</parent>
        <child>link_swivel_front</child>
        <axis>
          <xyz>0 1 0</xyz>
          <limit>
            <lower>-1e+16</lower>
            <upper>1e+16</upper>
          </limit>
          <dynamics>
            <spring_reference>0</spring_reference>
            <spring_stiffness>0</spring_stiffness>
          </dynamics>
        </axis>
      </joint>
      <link name='link_swivel_front'>
        <pose relative_to='joint_swivel_front'>0 0 0 0 -0 0</pose>
        <inertial>
          <pose>0.007514 -0.063827 0 0 -0 0</pose>
          <mass>1</mass>
          <inertia>
            <ixx>1</ixx>
            <ixy>0</ixy>
            <ixz>0</ixz>
            <iyy>1</iyy>
            <iyz>0</iyz>
            <izz>1</izz>
          </inertia>
        </inertial>
        <collision name='link_swivel_front_collision'>
          <pose>0 0 0 0 -0 0</pose>
          <geometry>
            <mesh>
              <scale>1 1 1</scale>
              <uri>model://terp2/meshes/link_swivel_front.STL</uri>
            </mesh>
          </geometry>
          <max_contacts>10</max_contacts>
          <surface>
            <contact>
              <ode/>
            </contact>
            <bounce/>
            <friction>
              <torsional>
                <ode/>
              </torsional>
              <ode/>
            </friction>
          </surface>
        </collision>
        <visual name='link_swivel_front_visual'>
          <pose>0 0 0 0 -0 0</pose>
          <geometry>
            <mesh>
              <scale>1 1 1</scale>
              <uri>model://terp2/meshes/link_swivel_front.STL</uri>
            </mesh>
          </geometry>
        </visual>
        <self_collide>0</self_collide>
        <enable_wind>0</enable_wind>
        <kinematic>0</kinematic>
      </link>
      <joint name='joint_swivelwheel_front' type='revolute'>
        <pose relative_to='link_swivel_front'>0 -0.0775 0 3.14159 -1.57079 3.14159</pose>
        <parent>link_swivel_front</parent>
        <child>link_swivelwheel_front</child>
        <axis>
          <xyz>0 0 1</xyz>
          <limit>
            <lower>-1e+16</lower>
            <upper>1e+16</upper>
          </limit>
          <dynamics>
            <spring_reference>0</spring_reference>
            <spring_stiffness>0</spring_stiffness>
          </dynamics>
        </axis>
      </joint>
      <link name='link_swivelwheel_front'>
        <pose relative_to='joint_swivelwheel_front'>0 0 0 0 -0 0</pose>
        <inertial>
          <pose>0 0 0 0 -0 0</pose>
          <mass>20</mass>
          <inertia>
            <ixx>20</ixx>
            <ixy>0</ixy>
            <ixz>0</ixz>
            <iyy>20</iyy>
            <iyz>0</iyz>
            <izz>20</izz>
          </inertia>
        </inertial>
        <collision name='link_swivelwheel_front_collision'>
          <pose>0 0 0 0 -0 0</pose>
          <geometry>
            <mesh>
              <scale>1 1 1</scale>
              <uri>model://terp2/meshes/link_swivelwheel_front.STL</uri>
            </mesh>
          </geometry>
          <max_contacts>10</max_contacts>
          <surface>
            <contact>
              <ode/>
            </contact>
            <bounce/>
            <friction>
              <torsional>
                <ode/>
              </torsional>
              <ode/>
            </friction>
          </surface>
        </collision>
        <visual name='link_swivelwheel_front_visual'>
          <pose>0 0 0 0 -0 0</pose>
          <geometry>
            <mesh>
              <scale>1 1 1</scale>
              <uri>model://terp2/meshes/link_swivelwheel_front.STL</uri>
            </mesh>
          </geometry>
        </visual>
        <self_collide>0</self_collide>
        <enable_wind>0</enable_wind>
        <kinematic>0</kinematic>
      </link>
      <static>0</static>
      <plugin name='gazebo_ros2_control' filename='libgazebo_ros2_control.so'>
        <parameters>/mnt/enpm662p2/project2/install/terp2/share/terp2/config/control.yaml</parameters>
      </plugin>
      <pose>0 0 0.8 0 -0 0</pose>
    </model>
    <model name='cafe_table'>
      <static>1</static>
      <link name='link'>
        <collision name='surface'>
          <pose>0 0 0.755 0 -0 0</pose>
          <geometry>
            <box>
              <size>0.913 0.913 0.04</size>
            </box>
          </geometry>
          <max_contacts>10</max_contacts>
          <surface>
            <contact>
              <ode/>
            </contact>
            <bounce/>
            <friction>
              <torsional>
                <ode/>
              </torsional>
              <ode/>
            </friction>
          </surface>
        </collision>
        <collision name='column'>
          <pose>0 0 0.37 0 -0 0</pose>
          <geometry>
            <box>
              <size>0.042 0.042 0.74</size>
            </box>
          </geometry>
          <max_contacts>10</max_contacts>
          <surface>
            <contact>
              <ode/>
            </contact>
            <bounce/>
            <friction>
              <torsional>
                <ode/>
              </torsional>
              <ode/>
            </friction>
          </surface>
        </collision>
        <collision name='base'>
          <pose>0 0 0.02 0 -0 0</pose>
          <geometry>
            <box>
              <size>0.56 0.56 0.04</size>
            </box>
          </geometry>
          <max_contacts>10</max_contacts>
          <surface>
            <contact>
              <ode/>
            </contact>
            <bounce/>
            <friction>
              <torsional>
                <ode/>
              </torsional>
              <ode/>
            </friction>
          </surface>
        </collision>
        <visual name='visual'>
          <geometry>
            <mesh>
              <uri>model://cafe_table/meshes/cafe_table.dae</uri>
            </mesh>
          </geometry>
        </visual>
        <self_collide>0</self_collide>
        <enable_wind>0</enable_wind>
        <kinematic>0</kinematic>
      </link>
      <pose>-3.17441 2.61787 0 0 -0 0</pose>
    </model>
    <model name='bookshelf'>
      <static>1</static>
      <link name='link'>
        <inertial>
          <mass>1</mass>
        </inertial>
        <collision name='back'>
          <pose>0 0.005 0.6 0 -0 0</pose>
          <geometry>
            <box>
              <size>0.9 0.01 1.2</size>
            </box>
          </geometry>
          <max_contacts>10</max_contacts>
          <surface>
            <contact>
              <ode/>
            </contact>
            <bounce/>
            <friction>
              <torsional>
                <ode/>
              </torsional>
              <ode/>
            </friction>
          </surface>
        </collision>
        <visual name='visual1'>
          <pose>0 0.005 0.6 0 -0 0</pose>
          <geometry>
            <box>
              <size>0.9 0.01 1.2</size>
            </box>
          </geometry>
          <material>
            <script>
              <uri>file://media/materials/scripts/gazebo.material</uri>
              <name>Gazebo/Wood</name>
            </script>
          </material>
        </visual>
        <collision name='left_side'>
          <pose>0.45 -0.195 0.6 0 -0 0</pose>
          <geometry>
            <box>
              <size>0.02 0.4 1.2</size>
            </box>
          </geometry>
          <max_contacts>10</max_contacts>
          <surface>
            <contact>
              <ode/>
            </contact>
            <bounce/>
            <friction>
              <torsional>
                <ode/>
              </torsional>
              <ode/>
            </friction>
          </surface>
        </collision>
        <visual name='visual2'>
          <pose>0.45 -0.195 0.6 0 -0 0</pose>
          <geometry>
            <box>
              <size>0.02 0.4 1.2</size>
            </box>
          </geometry>
          <material>
            <script>
              <uri>file://media/materials/scripts/gazebo.material</uri>
              <name>Gazebo/Wood</name>
            </script>
          </material>
        </visual>
        <collision name='right_side'>
          <pose>-0.45 -0.195 0.6 0 -0 0</pose>
          <geometry>
            <box>
              <size>0.02 0.4 1.2</size>
            </box>
          </geometry>
          <max_contacts>10</max_contacts>
          <surface>
            <contact>
              <ode/>
            </contact>
            <bounce/>
            <friction>
              <torsional>
                <ode/>
              </torsional>
              <ode/>
            </friction>
          </surface>
        </collision>
        <visual name='visual3'>
          <pose>-0.45 -0.195 0.6 0 -0 0</pose>
          <geometry>
            <box>
              <size>0.02 0.4 1.2</size>
            </box>
          </geometry>
          <material>
            <script>
              <uri>file://media/materials/scripts/gazebo.material</uri>
              <name>Gazebo/Wood</name>
            </script>
          </material>
        </visual>
        <collision name='bottom'>
          <pose>0 -0.195 0.03 0 -0 0</pose>
          <geometry>
            <box>
              <size>0.88 0.4 0.06</size>
            </box>
          </geometry>
          <max_contacts>10</max_contacts>
          <surface>
            <contact>
              <ode/>
            </contact>
            <bounce/>
            <friction>
              <torsional>
                <ode/>
              </torsional>
              <ode/>
            </friction>
          </surface>
        </collision>
        <visual name='visual4'>
          <pose>0 -0.195 0.03 0 -0 0</pose>
          <geometry>
            <box>
              <size>0.88 0.4 0.06</size>
            </box>
          </geometry>
          <material>
            <script>
              <uri>file://media/materials/scripts/gazebo.material</uri>
              <name>Gazebo/Wood</name>
            </script>
          </material>
        </visual>
        <collision name='top'>
          <pose>0 -0.195 1.19 0 -0 0</pose>
          <geometry>
            <box>
              <size>0.88 0.4 0.02</size>
            </box>
          </geometry>
          <max_contacts>10</max_contacts>
          <surface>
            <contact>
              <ode/>
            </contact>
            <bounce/>
            <friction>
              <torsional>
                <ode/>
              </torsional>
              <ode/>
            </friction>
          </surface>
        </collision>
        <visual name='visual5'>
          <pose>0 -0.195 1.19 0 -0 0</pose>
          <geometry>
            <box>
              <size>0.88 0.4 0.02</size>
            </box>
          </geometry>
          <material>
            <script>
              <uri>file://media/materials/scripts/gazebo.material</uri>
              <name>Gazebo/Wood</name>
            </script>
          </material>
        </visual>
        <collision name='low_shelf'>
          <pose>0 -0.195 0.43 0 -0 0</pose>
          <geometry>
            <box>
              <size>0.88 0.4 0.02</size>
            </box>
          </geometry>
          <max_contacts>10</max_contacts>
          <surface>
            <contact>
              <ode/>
            </contact>
            <bounce/>
            <friction>
              <torsional>
                <ode/>
              </torsional>
              <ode/>
            </friction>
          </surface>
        </collision>
        <visual name='visual6'>
          <pose>0 -0.195 0.43 0 -0 0</pose>
          <geometry>
            <box>
              <size>0.88 0.4 0.02</size>
            </box>
          </geometry>
          <material>
            <script>
              <uri>file://media/materials/scripts/gazebo.material</uri>
              <name>Gazebo/Wood</name>
            </script>
          </material>
        </visual>
        <collision name='high_shelf'>
          <pose>0 -0.195 0.8 0 -0 0</pose>
          <geometry>
            <box>
              <size>0.88 0.4 0.02</size>
            </box>
          </geometry>
          <max_contacts>10</max_contacts>
          <surface>
            <contact>
              <ode/>
            </contact>
            <bounce/>
            <friction>
              <torsional>
                <ode/>
              </torsional>
              <ode/>
            </friction>
          </surface>
        </collision>
        <visual name='visual7'>
          <pose>0 -0.195 0.8 0 -0 0</pose>
          <geometry>
            <box>
              <size>0.88 0.4 0.02</size>
            </box>
          </geometry>
          <material>
            <script>
              <uri>file://media/materials/scripts/gazebo.material</uri>
              <name>Gazebo/Wood</name>
            </script>
          </material>
        </visual>
        <self_collide>0</self_collide>
        <enable_wind>0</enable_wind>
        <kinematic>0</kinematic>
      </link>
      <pose>-1.64683 6.26049 0 0 -0 0</pose>
    </model>
    <state world_name='default'>
      <sim_time>3103 943000000</sim_time>
      <real_time>2099 598170763</real_time>
      <wall_time>1733001114 122162183</wall_time>
      <iterations>2079047</iterations>
      <model name='Book'>
        <pose>-1.42722 0.023897 0.9147 3.14159 -0 3.14159</pose>
        <scale>1 1 1</scale>
        <link name='link_0'>
          <pose>-1.42722 0.023897 0.9147 3.14159 -0 3.14159</pose>
          <velocity>0 0 0 0 -0 0</velocity>
          <acceleration>0 0 0 0 -0 0</acceleration>
          <wrench>0 0 0 0 -0 0</wrench>
        </link>
      </model>
      <model name='Book_clone'>
        <pose>-1.43408 -0.618079 0.9147 3.14159 -0 3.14159</pose>
        <scale>1 1 1</scale>
        <link name='link_0'>
          <pose>-1.43408 -0.618079 0.9147 3.14159 -0 3.14159</pose>
          <velocity>0 0 0 0 -0 0</velocity>
          <acceleration>0 0 0 0 -0 0</acceleration>
          <wrench>0 0 0 0 -0 0</wrench>
        </link>
      </model>
      <model name='bookshelf'>
        <pose>-0.019234 -3.0017 0 0 0 -3.14107</pose>
        <scale>1 1 1</scale>
        <link name='link'>
          <pose>-0.019234 -3.0017 0 0 0 -3.14107</pose>
          <velocity>0 0 0 0 -0 0</velocity>
          <acceleration>0 0 0 0 -0 0</acceleration>
          <wrench>0 0 0 0 -0 0</wrench>
        </link>
      </model>
      <model name='cafe_table'>
        <pose>-1.83397 -0.298848 0 0 -0 0</pose>
        <scale>1 1 1</scale>
        <link name='link'>
          <pose>-1.83397 -0.298848 0 0 -0 0</pose>
          <velocity>0 0 0 0 -0 0</velocity>
          <acceleration>0 0 0 0 -0 0</acceleration>
          <wrench>0 0 0 0 -0 0</wrench>
        </link>
      </model>
      <model name='ground_plane'>
        <pose>0 0 0 0 -0 0</pose>
        <scale>1 1 1</scale>
        <link name='link'>
          <pose>0 0 0 0 -0 0</pose>
          <velocity>0 0 0 0 -0 0</velocity>
          <acceleration>0 0 0 0 -0 0</acceleration>
          <wrench>0 0 0 0 -0 0</wrench>
        </link>
      </model>
      <model name='terp2'>
        <pose>0.497203 -0.160004 0.709832 -6e-06 1e-06 -1.71581</pose>
        <scale>1 1 1</scale>
        <link name='base_link'>
          <pose>0.497203 -0.160004 0.709832 -6e-06 1e-06 -1.71581</pose>
          <velocity>0.001236 -0.000142 -0.000923 0.00014 0.00122 -9e-06</velocity>
          <acceleration>0.321173 -0.034219 -1.84557 -2.86202 0.701165 3.13998</acceleration>
          <wrench>17.6645 -1.88203 -101.506 0 -0 0</wrench>
        </link>
        <link name='link_arm_1'>
          <pose>0.507098 -0.161449 0.70983 1.57079 1e-06 -1.71581</pose>
          <velocity>0.000585 -7.1e-05 -0.000869 0.000136 0.001191 4.2e-05</velocity>
          <acceleration>1.44622 -0.167209 -1.76637 -2.86577 0.730462 -3.09194</acceleration>
          <wrench>1.44622 -0.167209 -1.76637 0 -0 0</wrench>
        </link>
        <link name='link_arm_2'>
          <pose>0.489986 -0.20943 0.769829 4e-06 -0.870788 2.99657</pose>
          <velocity>0.003559 -0.000506 0.001671 -0.001332 -0.008872 4.5e-05</velocity>
          <acceleration>-1.05716 0.204536 -3.82079 -1.1924 -1.36833 0.052205</acceleration>
          <wrench>-1.05716 0.204536 -3.82079 0 -0 0</wrench>
        </link>
        <link name='link_arm_3'>
          <pose>-0.051856 -0.130295 1.41994 -3.14158 1.0708 2.99658</pose>
          <velocity>-0.007301 0.001096 -0.004446 -0.001006 -0.006632 4.7e-05</velocity>
          <acceleration>-1.79722 0.284538 -6.89187 -0.866274 0.871087 0.053779</acceleration>
          <wrench>-1.79722 0.284538 -6.89187 0 -0 0</wrench>
        </link>
        <link name='link_arm_4'>
          <pose>-0.393203 0.020565 0.761749 -3.14156 -1.2708 2.99654</pose>
          <velocity>-0.00071 6.6e-05 -0.008017 -0.000222 -0.001238 4.5e-05</velocity>
          <acceleration>-0.038611 -0.007219 -7.85417 -0.082023 -0.018192 0.052566</acceleration>
          <wrench>-0.038611 -0.007219 -7.85417 0 -0 0</wrench>
        </link>
        <link name='link_arm_5'>
          <pose>-0.42984 0.076447 0.905048 -1.42355 0.262342 -2.76715</pose>
          <velocity>-0.000927 9.8e-05 -0.008046 -0.000194 -0.001235 -6.5e-05</velocity>
          <acceleration>-0.054216 0.000771 -7.83062 -0.054087 -0.015274 -0.057976</acceleration>
          <wrench>-0.054216 0.000771 -7.83062 0 -0 0</wrench>
        </link>
        <link name='link_drivewheel_left'>
          <pose>0.458182 -0.427169 0.049828 1.5708 -0.826738 2.99657</pose>
          <velocity>-4.1e-05 5e-06 -0.001745 -0.000227 -0.001207 -1e-05</velocity>
          <acceleration>-0.163558 0.022565 -2.65999 -0.087141 0.012727 -0.002358</acceleration>
          <wrench>-3.27116 0.451299 -53.1997 0 -0 0</wrench>
        </link>
        <link name='link_drivewheel_right'>
          <pose>0.536217 0.107163 0.049828 1.5708 -0.826738 2.99657</pose>
          <velocity>-3.3e-05 3e-06 -0.001653 -0.000206 -0.001211 -8e-06</velocity>
          <acceleration>-0.159278 0.020856 -2.58507 -0.065888 0.009623 -0.000885</acceleration>
          <wrench>-3.18556 0.41712 -51.7014 0 -0 0</wrench>
        </link>
        <link name='link_gripper_base'>
          <pose>-0.489405 0.060921 0.939847 -2.87851 -0.073828 -1.21622</pose>
          <velocity>-0.00105 0.000115 -0.008035 0.000148 -0.001086 3.3e-05</velocity>
          <acceleration>-0.066846 0.005018 -7.80906 0.287252 0.134228 0.039898</acceleration>
          <wrench>-0.066846 0.005018 -7.80906 0 -0 0</wrench>
        </link>
        <link name='link_gripper_gear'>
          <pose>-0.624235 0.007935 0.900945 -0.266294 0.170352 1.89903</pose>
          <velocity>-0.000985 0.000117 -0.008268 -0.000134 -0.001203 -4.8e-05</velocity>
          <acceleration>-0.070648 0.007964 -7.80398 0.005262 0.016929 -0.041295</acceleration>
          <wrench>-0.070648 0.007964 -7.80398 0 -0 0</wrench>
        </link>
        <link name='link_gripper_pad1'>
          <pose>-0.669178 -0.009726 0.887978 -1.29368 -1.29778 -3.05436</pose>
          <velocity>-0.001006 0.000234 -0.008321 0.000146 -0.001074 3.2e-05</velocity>
          <acceleration>-0.05864 0.117982 -8.02895 0.156398 -1.05385 0.091984</acceleration>
          <wrench>-0.05864 0.117982 -8.02895 0 -0 0</wrench>
        </link>
        <link name='link_gripper_pad2'>
          <pose>-0.596507 0.077714 0.910383 -1.81114 1.29779 0.087278</pose>
          <velocity>-0.001063 0.000219 -0.008158 0.000146 -0.001074 3.2e-05</velocity>
          <acceleration>-0.038753 0.108707 -8.00606 0.155968 -1.05389 0.091791</acceleration>
          <wrench>-0.038753 0.108707 -8.00606 0 -0 0</wrench>
        </link>
        <link name='link_swivel_back'>
          <pose>0.754298 -0.19755 0.114847 1.57081 -1e-06 1.42578</pose>
          <velocity>0.000123 -1.3e-05 -0.004302 9.9e-05 0.001193 8.7e-05</velocity>
          <acceleration>-0.152961 0.018807 -5.54496 -2.90241 0.727887 -3.04782</acceleration>
          <wrench>-0.152961 0.018807 -5.54496 0 -0 0</wrench>
        </link>
        <link name='link_swivel_front'>
          <pose>0.240097 -0.122455 0.114852 1.57079 1e-06 -1.71581</pose>
          <velocity>0.000112 -5e-06 0.002794 9.5e-05 0.001195 6.2e-05</velocity>
          <acceleration>-0.162617 0.022046 2.1918 -2.90695 0.726361 -3.07288</acceleration>
          <wrench>-0.162617 0.022046 2.1918 0 -0 0</wrench>
        </link>
        <link name='link_swivelwheel_back'>
          <pose>0.754297 -0.19755 0.037365 -1.5708 -0.992099 -0.14502</pose>
          <velocity>2.2e-05 -6e-06 -0.007411 -0.000118 1.7e-05 8.7e-05</velocity>
          <acceleration>0.021205 -0.001314 -14.8225 -0.235515 0.034397 -0.004744</acceleration>
          <wrench>0.424093 -0.026277 -296.45 0 -0 0</wrench>
        </link>
        <link name='link_swivelwheel_front'>
          <pose>0.240097 -0.122455 0.037372 1.57073 -1.4881 2.99663</pose>
          <velocity>-0 4e-06 0.006217 -0.000114 1.7e-05 6.2e-05</velocity>
          <acceleration>-0.024395 0.010953 12.4342 -0.228298 0.033346 0.003405</acceleration>
          <wrench>-0.487902 0.219069 248.684 0 -0 0</wrench>
        </link>
      </model>
      <light name='sun'>
        <pose>0 0 10 0 -0 0</pose>
      </light>
    </state>
    <model name='Book'>
      <link name='link_0'>
        <inertial>
          <mass>1</mass>
          <inertia>
            <ixx>0.166667</ixx>
            <ixy>0</ixy>
            <ixz>0</ixz>
            <iyy>0.166667</iyy>
            <iyz>0</iyz>
            <izz>0.166667</izz>
          </inertia>
          <pose>0 0 0 0 -0 0</pose>
        </inertial>
        <pose>-1e-06 0 0 0 -0 0</pose>
        <visual name='visual'>
          <pose>0 0 0 0 -0 0</pose>
          <geometry>
            <mesh>
              <uri>/mnt/enpm662p2/solidworks/textbook_urdf/meshes/base_link.STL</uri>
              <scale>1 1 1</scale>
            </mesh>
          </geometry>
          <material>
            <lighting>1</lighting>
            <script>
              <uri>file://media/materials/scripts/gazebo.material</uri>
              <name>Gazebo/Grey</name>
            </script>
            <shader type='pixel'/>
          </material>
          <transparency>0</transparency>
          <cast_shadows>1</cast_shadows>
        </visual>
        <collision name='collision'>
          <laser_retro>0</laser_retro>
          <max_contacts>10</max_contacts>
          <pose>0 0 0 0 -0 0</pose>
          <geometry>
            <mesh>
              <uri>/mnt/enpm662p2/solidworks/textbook_urdf/meshes/base_link.STL</uri>
              <scale>1 1 1</scale>
            </mesh>
          </geometry>
          <surface>
            <friction>
              <ode>
                <mu>1</mu>
                <mu2>1</mu2>
                <fdir1>0 0 0</fdir1>
                <slip1>0</slip1>
                <slip2>0</slip2>
              </ode>
              <torsional>
                <coefficient>1</coefficient>
                <patch_radius>0</patch_radius>
                <surface_radius>0</surface_radius>
                <use_patch_radius>1</use_patch_radius>
                <ode>
                  <slip>0</slip>
                </ode>
              </torsional>
            </friction>
            <bounce>
              <restitution_coefficient>0</restitution_coefficient>
              <threshold>1e+06</threshold>
            </bounce>
            <contact>
              <collide_without_contact>0</collide_without_contact>
              <collide_without_contact_bitmask>1</collide_without_contact_bitmask>
              <collide_bitmask>1</collide_bitmask>
              <ode>
                <soft_cfm>0</soft_cfm>
                <soft_erp>0.2</soft_erp>
                <kp>1e+13</kp>
                <kd>1</kd>
                <max_vel>0.01</max_vel>
                <min_depth>0</min_depth>
              </ode>
              <bullet>
                <split_impulse>1</split_impulse>
                <split_impulse_penetration_threshold>-0.01</split_impulse_penetration_threshold>
                <soft_cfm>0</soft_cfm>
                <soft_erp>0.2</soft_erp>
                <kp>1e+13</kp>
                <kd>1</kd>
              </bullet>
            </contact>
          </surface>
        </collision>
        <self_collide>0</self_collide>
        <enable_wind>0</enable_wind>
        <kinematic>0</kinematic>
      </link>
      <static>0</static>
      <allow_auto_disable>1</allow_auto_disable>
      <pose>-1.10076 -0.756011 0 0 -0 0</pose>
    </model>
    <model name='Book_clone'>
      <link name='link_0'>
        <inertial>
          <mass>1</mass>
          <inertia>
            <ixx>0.166667</ixx>
            <ixy>0</ixy>
            <ixz>0</ixz>
            <iyy>0.166667</iyy>
            <iyz>0</iyz>
            <izz>0.166667</izz>
          </inertia>
          <pose>0 0 0 0 -0 0</pose>
        </inertial>
        <pose>-1e-06 0 0 0 -0 0</pose>
        <visual name='visual'>
          <pose>0 0 0 0 -0 0</pose>
          <geometry>
            <mesh>
              <uri>/mnt/enpm662p2/solidworks/textbook_urdf/meshes/base_link.STL</uri>
              <scale>1 1 1</scale>
            </mesh>
          </geometry>
          <material>
            <lighting>1</lighting>
            <script>
              <uri>file://media/materials/scripts/gazebo.material</uri>
              <name>Gazebo/Grey</name>
            </script>
            <shader type='pixel'/>
          </material>
          <transparency>0</transparency>
          <cast_shadows>1</cast_shadows>
        </visual>
        <collision name='collision'>
          <laser_retro>0</laser_retro>
          <max_contacts>10</max_contacts>
          <pose>0 0 0 0 -0 0</pose>
          <geometry>
            <mesh>
              <uri>/mnt/enpm662p2/solidworks/textbook_urdf/meshes/base_link.STL</uri>
              <scale>1 1 1</scale>
            </mesh>
          </geometry>
          <surface>
            <friction>
              <ode>
                <mu>1</mu>
                <mu2>1</mu2>
                <fdir1>0 0 0</fdir1>
                <slip1>0</slip1>
                <slip2>0</slip2>
              </ode>
              <torsional>
                <coefficient>1</coefficient>
                <patch_radius>0</patch_radius>
                <surface_radius>0</surface_radius>
                <use_patch_radius>1</use_patch_radius>
                <ode>
                  <slip>0</slip>
                </ode>
              </torsional>
            </friction>
            <bounce>
              <restitution_coefficient>0</restitution_coefficient>
              <threshold>1e+06</threshold>
            </bounce>
            <contact>
              <collide_without_contact>0</collide_without_contact>
              <collide_without_contact_bitmask>1</collide_without_contact_bitmask>
              <collide_bitmask>1</collide_bitmask>
              <ode>
                <soft_cfm>0</soft_cfm>
                <soft_erp>0.2</soft_erp>
                <kp>1e+13</kp>
                <kd>1</kd>
                <max_vel>0.01</max_vel>
                <min_depth>0</min_depth>
              </ode>
              <bullet>
                <split_impulse>1</split_impulse>
                <split_impulse_penetration_threshold>-0.01</split_impulse_penetration_threshold>
                <soft_cfm>0</soft_cfm>
                <soft_erp>0.2</soft_erp>
                <kp>1e+13</kp>
                <kd>1</kd>
              </bullet>
            </contact>
          </surface>
        </collision>
        <self_collide>0</self_collide>
        <enable_wind>0</enable_wind>
        <kinematic>0</kinematic>
      </link>
      <static>0</static>
      <allow_auto_disable>1</allow_auto_disable>
      <pose>-1.18925 -1.15818 0 0 -0 0</pose>
    </model>
  </world>
</sdf>
